INFO 2025-04-04 19:32:42,035 autoreload 69468 75756 Watching for file changes with StatReloader
INFO 2025-04-04 19:47:14,674 autoreload 10752 28376 Watching for file changes with StatReloader
INFO 2025-04-04 19:49:15,526 autoreload 7052 40232 Watching for file changes with StatReloader
INFO 2025-04-04 19:50:41,156 autoreload 7052 40232 C:\WISENTIA_Q\wisentia\wisentia_backend\wallet\views.py changed, reloading.
INFO 2025-04-04 19:50:42,076 autoreload 76132 65600 Watching for file changes with StatReloader
INFO 2025-04-04 19:50:50,998 autoreload 17708 32388 Watching for file changes with StatReloader
WARNING 2025-04-04 19:50:56,746 log 17708 62576 Not Found: /
WARNING 2025-04-04 19:50:56,747 basehttp 17708 62576 "GET / HTTP/1.1" 404 3655
WARNING 2025-04-04 19:50:57,811 log 17708 62576 Not Found: /favicon.ico
WARNING 2025-04-04 19:50:57,813 basehttp 17708 62576 "GET /favicon.ico HTTP/1.1" 404 3706
INFO 2025-04-04 19:51:09,176 basehttp 17708 62576 "GET /api/courses HTTP/1.1" 301 0
INFO 2025-04-04 19:51:09,249 basehttp 17708 46064 "GET /api/courses/ HTTP/1.1" 200 5152
INFO 2025-04-04 19:51:09,434 basehttp 17708 46064 "GET /static/rest_framework/css/bootstrap.min.css HTTP/1.1" 200 121457
INFO 2025-04-04 19:51:09,457 basehttp 17708 46064 "GET /static/rest_framework/js/csrf.js HTTP/1.1" 200 1793
INFO 2025-04-04 19:51:09,465 basehttp 17708 60840 "GET /static/rest_framework/css/bootstrap-tweaks.css HTTP/1.1" 200 3426
INFO 2025-04-04 19:51:09,468 basehttp 17708 78876 "GET /static/rest_framework/css/prettify.css HTTP/1.1" 200 817
INFO 2025-04-04 19:51:09,470 basehttp 17708 76544 "GET /static/rest_framework/css/default.css HTTP/1.1" 200 1152
INFO 2025-04-04 19:51:09,491 basehttp 17708 76544 "GET /static/rest_framework/js/load-ajax-form.js HTTP/1.1" 200 59
INFO 2025-04-04 19:51:09,495 basehttp 17708 1932 "GET /static/rest_framework/js/ajax-form.js HTTP/1.1" 200 3796
INFO 2025-04-04 19:51:09,499 basehttp 17708 78876 "GET /static/rest_framework/js/default.js HTTP/1.1" 200 1268
INFO 2025-04-04 19:51:09,503 basehttp 17708 76544 "GET /static/rest_framework/img/grid.png HTTP/1.1" 200 1458
INFO 2025-04-04 19:51:09,510 basehttp 17708 60840 "GET /static/rest_framework/js/prettify-min.js HTTP/1.1" 200 13632
INFO 2025-04-04 19:51:09,512 basehttp 17708 46064 "GET /static/rest_framework/js/bootstrap.min.js HTTP/1.1" 200 39680
INFO 2025-04-04 19:51:09,545 basehttp 17708 41552 "GET /static/rest_framework/js/jquery-3.7.1.min.js HTTP/1.1" 200 87533
WARNING 2025-04-04 19:51:15,622 log 17708 41552 Not Found: /
WARNING 2025-04-04 19:51:15,622 basehttp 17708 41552 "GET / HTTP/1.1" 404 3655
WARNING 2025-04-04 19:51:23,373 log 17708 41552 Not Found: /api/subscriptions/
WARNING 2025-04-04 19:51:23,374 basehttp 17708 41552 "GET /api/subscriptions/ HTTP/1.1" 404 5296
WARNING 2025-04-04 19:51:43,719 log 17708 41552 Not Found: /api/community
WARNING 2025-04-04 19:51:43,719 basehttp 17708 41552 "GET /api/community HTTP/1.1" 404 3712
WARNING 2025-04-04 19:51:52,809 log 17708 41552 Not Found: /api/community/
WARNING 2025-04-04 19:51:52,810 basehttp 17708 41552 "GET /api/community/ HTTP/1.1" 404 5030
INFO 2025-04-04 19:53:27,247 autoreload 17708 32388 C:\WISENTIA_Q\wisentia\wisentia_backend\wisentia_backend\urls.py changed, reloading.
INFO 2025-04-04 19:53:28,225 autoreload 74252 79456 Watching for file changes with StatReloader
INFO 2025-04-04 19:53:46,023 autoreload 74252 79456 C:\WISENTIA_Q\wisentia\wisentia_backend\wisentia_backend\urls.py changed, reloading.
INFO 2025-04-04 19:53:46,896 autoreload 71992 76060 Watching for file changes with StatReloader
WARNING 2025-04-04 19:54:02,390 log 71992 14832 Not Found: /api/community/
WARNING 2025-04-04 19:54:02,391 basehttp 71992 14832 "GET /api/community/ HTTP/1.1" 404 5455
INFO 2025-04-04 19:54:07,179 basehttp 71992 14832 "GET /swagger/ HTTP/1.1" 200 2215
INFO 2025-04-04 19:54:07,390 basehttp 71992 14832 "GET /static/drf-yasg/style.css HTTP/1.1" 200 1047
INFO 2025-04-04 19:54:07,395 basehttp 71992 77324 "GET /static/drf-yasg/swagger-ui-dist/swagger-ui.css HTTP/1.1" 200 145206
INFO 2025-04-04 19:54:07,421 basehttp 71992 14832 "GET /static/drf-yasg/swagger-ui-init.js HTTP/1.1" 200 15480
INFO 2025-04-04 19:54:07,430 basehttp 71992 76492 "GET /static/drf-yasg/insQ.min.js HTTP/1.1" 200 2093
INFO 2025-04-04 19:54:07,449 basehttp 71992 75892 "GET /static/drf-yasg/swagger-ui-dist/swagger-ui-bundle.js HTTP/1.1" 200 1046583
INFO 2025-04-04 19:54:07,453 basehttp 71992 79420 "GET /static/drf-yasg/immutable.min.js HTTP/1.1" 200 56904
INFO 2025-04-04 19:54:07,517 basehttp 71992 69612 "GET /static/drf-yasg/swagger-ui-dist/swagger-ui-standalone-preset.js HTTP/1.1" 200 322863
INFO 2025-04-04 19:54:07,629 basehttp 71992 69612 "GET /swagger/?format=openapi HTTP/1.1" 200 25662
INFO 2025-04-04 19:54:07,636 basehttp 71992 79420 "GET /static/drf-yasg/swagger-ui-dist/favicon-32x32.png HTTP/1.1" 200 628
WARNING 2025-04-04 19:54:38,617 log 71992 79420 Forbidden: /api/admin/content/
WARNING 2025-04-04 19:54:38,617 basehttp 71992 79420 "GET /api/admin/content/ HTTP/1.1" 403 58
INFO 2025-04-04 22:42:45,579 autoreload 71992 76060 C:\WISENTIA_Q\wisentia\wisentia_backend\courses\views.py changed, reloading.
INFO 2025-04-04 22:42:46,618 autoreload 36236 71636 Watching for file changes with StatReloader
INFO 2025-04-04 22:43:30,573 autoreload 36236 71636 C:\WISENTIA_Q\wisentia\wisentia_backend\courses\views.py changed, reloading.
INFO 2025-04-04 22:43:31,454 autoreload 81616 39380 Watching for file changes with StatReloader
INFO 2025-04-04 22:44:48,792 autoreload 79144 44824 Watching for file changes with StatReloader
INFO 2025-04-04 22:48:48,732 autoreload 77840 54608 Watching for file changes with StatReloader
INFO 2025-04-04 22:49:50,220 basehttp 77840 73436 "GET /swagger/ HTTP/1.1" 200 2215
INFO 2025-04-04 22:49:50,241 basehttp 77840 73436 "GET /static/drf-yasg/style.css HTTP/1.1" 304 0
INFO 2025-04-04 22:49:50,246 basehttp 77840 73436 "GET /static/drf-yasg/swagger-ui-dist/swagger-ui.css HTTP/1.1" 304 0
INFO 2025-04-04 22:49:50,258 basehttp 77840 10656 "GET /static/drf-yasg/immutable.min.js HTTP/1.1" 304 0
INFO 2025-04-04 22:49:50,258 basehttp 77840 18332 "GET /static/drf-yasg/swagger-ui-dist/swagger-ui-bundle.js HTTP/1.1" 304 0
INFO 2025-04-04 22:49:50,258 basehttp 77840 28480 "GET /static/drf-yasg/insQ.min.js HTTP/1.1" 304 0
INFO 2025-04-04 22:49:50,258 basehttp 77840 53176 "GET /static/drf-yasg/swagger-ui-dist/swagger-ui-standalone-preset.js HTTP/1.1" 304 0
INFO 2025-04-04 22:49:50,259 basehttp 77840 69812 "GET /static/drf-yasg/swagger-ui-init.js HTTP/1.1" 304 0
INFO 2025-04-04 22:49:50,434 basehttp 77840 69812 "GET /swagger/?format=openapi HTTP/1.1" 200 27681
INFO 2025-04-04 22:49:50,435 basehttp 77840 53176 "GET /static/drf-yasg/swagger-ui-dist/favicon-32x32.png HTTP/1.1" 304 0
WARNING 2025-04-04 22:49:57,168 log 77840 69812 Not Found: /accounts/login/
WARNING 2025-04-04 22:49:57,169 basehttp 77840 69812 "GET /accounts/login/?next=/swagger/ HTTP/1.1" 404 4158
WARNING 2025-04-04 22:49:57,227 log 77840 69812 Not Found: /favicon.ico
WARNING 2025-04-04 22:49:57,228 basehttp 77840 69812 "GET /favicon.ico HTTP/1.1" 404 4131
INFO 2025-04-04 22:51:56,255 autoreload 77840 54608 C:\WISENTIA_Q\wisentia\wisentia_backend\wisentia_backend\settings.py changed, reloading.
INFO 2025-04-04 22:51:57,251 autoreload 80808 79992 Watching for file changes with StatReloader
INFO 2025-04-04 22:52:19,837 autoreload 80808 79992 C:\WISENTIA_Q\wisentia\wisentia_backend\users\views.py changed, reloading.
INFO 2025-04-04 22:52:20,668 autoreload 52288 27496 Watching for file changes with StatReloader
INFO 2025-04-04 22:52:34,136 autoreload 52288 27496 C:\WISENTIA_Q\wisentia\wisentia_backend\users\views.py changed, reloading.
INFO 2025-04-04 22:52:35,094 autoreload 81420 49620 Watching for file changes with StatReloader
INFO 2025-04-04 22:52:39,823 autoreload 81420 49620 C:\WISENTIA_Q\wisentia\wisentia_backend\users\views.py changed, reloading.
INFO 2025-04-04 22:52:40,772 autoreload 32536 76108 Watching for file changes with StatReloader
INFO 2025-04-04 22:52:59,935 autoreload 32536 76108 C:\WISENTIA_Q\wisentia\wisentia_backend\wallet\views.py changed, reloading.
INFO 2025-04-04 22:53:00,854 autoreload 36784 76392 Watching for file changes with StatReloader
INFO 2025-04-04 22:53:14,338 autoreload 36784 76392 C:\WISENTIA_Q\wisentia\wisentia_backend\wallet\views.py changed, reloading.
INFO 2025-04-04 22:53:15,263 autoreload 77164 81460 Watching for file changes with StatReloader
INFO 2025-04-04 22:54:04,703 autoreload 77164 81460 C:\WISENTIA_Q\wisentia\wisentia_backend\wisentia_backend\settings.py changed, reloading.
INFO 2025-04-04 22:54:05,678 autoreload 30888 78596 Watching for file changes with StatReloader
INFO 2025-04-04 22:54:18,047 autoreload 79636 61184 Watching for file changes with StatReloader
INFO 2025-04-04 22:54:51,949 autoreload 79636 61184 C:\WISENTIA_Q\wisentia\wisentia_backend\wallet\views.py changed, reloading.
INFO 2025-04-04 22:54:52,838 autoreload 62168 21944 Watching for file changes with StatReloader
INFO 2025-04-04 23:13:04,356 autoreload 62168 21944 C:\WISENTIA_Q\wisentia\wisentia_backend\wallet\views.py changed, reloading.
INFO 2025-04-04 23:13:05,265 autoreload 33440 81360 Watching for file changes with StatReloader
INFO 2025-04-04 23:14:04,528 autoreload 33440 81360 C:\WISENTIA_Q\wisentia\wisentia_backend\courses\views.py changed, reloading.
INFO 2025-04-04 23:14:05,415 autoreload 40884 76672 Watching for file changes with StatReloader
INFO 2025-04-04 23:14:12,325 autoreload 40884 76672 C:\WISENTIA_Q\wisentia\wisentia_backend\courses\views.py changed, reloading.
INFO 2025-04-04 23:14:13,108 autoreload 77636 69544 Watching for file changes with StatReloader
INFO 2025-04-04 23:14:45,400 autoreload 77636 69544 C:\WISENTIA_Q\wisentia\wisentia_backend\community\views.py changed, reloading.
INFO 2025-04-04 23:14:46,314 autoreload 57764 69712 Watching for file changes with StatReloader
INFO 2025-04-05 01:27:32,948 autoreload 89236 89580 Watching for file changes with StatReloader
INFO 2025-04-05 01:30:59,673 autoreload 4456 85268 Watching for file changes with StatReloader
ERROR 2025-04-05 01:31:29,831 middleware 4456 67324 API Error: ('23000', "[23000] [Microsoft][ODBC Driver 17 for SQL Server][SQL Server]Violation of UNIQUE KEY constraint 'UQ__Users__6D19B83B36C6A55E'. Cannot insert duplicate key in object 'dbo.Users'. The duplicate key value is (<NULL>). (2627) (SQLExecDirectW); [23000] [Microsoft][ODBC Driver 17 for SQL Server][SQL Server]The statement has been terminated. (3621)")
ERROR 2025-04-05 01:31:29,831 middleware 4456 67324 Traceback (most recent call last):
  File "C:\WISENTIA_Q\wisentia\venv\Lib\site-packages\django\db\backends\utils.py", line 105, in _execute
    return self.cursor.execute(sql, params)
           ^^^^^^^^^^^^^^^^^^^^^^^^^^^^^^^^
  File "C:\WISENTIA_Q\wisentia\venv\Lib\site-packages\mssql\base.py", line 677, in execute
    return self.cursor.execute(sql, params)
           ^^^^^^^^^^^^^^^^^^^^^^^^^^^^^^^^
pyodbc.IntegrityError: ('23000', "[23000] [Microsoft][ODBC Driver 17 for SQL Server][SQL Server]Violation of UNIQUE KEY constraint 'UQ__Users__6D19B83B36C6A55E'. Cannot insert duplicate key in object 'dbo.Users'. The duplicate key value is (<NULL>). (2627) (SQLExecDirectW); [23000] [Microsoft][ODBC Driver 17 for SQL Server][SQL Server]The statement has been terminated. (3621)")

The above exception was the direct cause of the following exception:

Traceback (most recent call last):
  File "C:\WISENTIA_Q\wisentia\venv\Lib\site-packages\django\core\handlers\base.py", line 197, in _get_response
    response = wrapped_callback(request, *callback_args, **callback_kwargs)
               ^^^^^^^^^^^^^^^^^^^^^^^^^^^^^^^^^^^^^^^^^^^^^^^^^^^^^^^^^^^^
  File "C:\WISENTIA_Q\wisentia\venv\Lib\site-packages\django\views\decorators\csrf.py", line 65, in _view_wrapper
    return view_func(request, *args, **kwargs)
           ^^^^^^^^^^^^^^^^^^^^^^^^^^^^^^^^^^^
  File "C:\WISENTIA_Q\wisentia\venv\Lib\site-packages\django\views\generic\base.py", line 104, in view
    return self.dispatch(request, *args, **kwargs)
           ^^^^^^^^^^^^^^^^^^^^^^^^^^^^^^^^^^^^^^^
  File "C:\WISENTIA_Q\wisentia\venv\Lib\site-packages\rest_framework\views.py", line 515, in dispatch
    response = self.handle_exception(exc)
               ^^^^^^^^^^^^^^^^^^^^^^^^^^
  File "C:\WISENTIA_Q\wisentia\venv\Lib\site-packages\rest_framework\views.py", line 475, in handle_exception
    self.raise_uncaught_exception(exc)
  File "C:\WISENTIA_Q\wisentia\venv\Lib\site-packages\rest_framework\views.py", line 486, in raise_uncaught_exception
    raise exc
  File "C:\WISENTIA_Q\wisentia\venv\Lib\site-packages\rest_framework\views.py", line 512, in dispatch
    response = handler(request, *args, **kwargs)
               ^^^^^^^^^^^^^^^^^^^^^^^^^^^^^^^^^
  File "C:\WISENTIA_Q\wisentia\venv\Lib\site-packages\rest_framework\decorators.py", line 50, in handler
    return func(*args, **kwargs)
           ^^^^^^^^^^^^^^^^^^^^^
  File "C:\WISENTIA_Q\wisentia\wisentia_backend\users\views.py", line 122, in register
    cursor.execute("""
  File "C:\WISENTIA_Q\wisentia\venv\Lib\site-packages\django\db\backends\utils.py", line 122, in execute
    return super().execute(sql, params)
           ^^^^^^^^^^^^^^^^^^^^^^^^^^^^
  File "C:\WISENTIA_Q\wisentia\venv\Lib\site-packages\django\db\backends\utils.py", line 79, in execute
    return self._execute_with_wrappers(
           ^^^^^^^^^^^^^^^^^^^^^^^^^^^^
  File "C:\WISENTIA_Q\wisentia\venv\Lib\site-packages\django\db\backends\utils.py", line 92, in _execute_with_wrappers
    return executor(sql, params, many, context)
           ^^^^^^^^^^^^^^^^^^^^^^^^^^^^^^^^^^^^
  File "C:\WISENTIA_Q\wisentia\venv\Lib\site-packages\django\db\backends\utils.py", line 100, in _execute
    with self.db.wrap_database_errors:
  File "C:\WISENTIA_Q\wisentia\venv\Lib\site-packages\django\db\utils.py", line 91, in __exit__
    raise dj_exc_value.with_traceback(traceback) from exc_value
  File "C:\WISENTIA_Q\wisentia\venv\Lib\site-packages\django\db\backends\utils.py", line 105, in _execute
    return self.cursor.execute(sql, params)
           ^^^^^^^^^^^^^^^^^^^^^^^^^^^^^^^^
  File "C:\WISENTIA_Q\wisentia\venv\Lib\site-packages\mssql\base.py", line 677, in execute
    return self.cursor.execute(sql, params)
           ^^^^^^^^^^^^^^^^^^^^^^^^^^^^^^^^
django.db.utils.IntegrityError: ('23000', "[23000] [Microsoft][ODBC Driver 17 for SQL Server][SQL Server]Violation of UNIQUE KEY constraint 'UQ__Users__6D19B83B36C6A55E'. Cannot insert duplicate key in object 'dbo.Users'. The duplicate key value is (<NULL>). (2627) (SQLExecDirectW); [23000] [Microsoft][ODBC Driver 17 for SQL Server][SQL Server]The statement has been terminated. (3621)")

ERROR 2025-04-05 01:31:29,832 log 4456 67324 Internal Server Error: /api/auth/register/
ERROR 2025-04-05 01:31:29,833 basehttp 4456 67324 "POST /api/auth/register/ HTTP/1.1" 500 4821
WARNING 2025-04-05 01:31:38,715 log 4456 81592 Unauthorized: /api/auth/login/
WARNING 2025-04-05 01:31:38,716 basehttp 4456 81592 "POST /api/auth/login/ HTTP/1.1" 401 31
WARNING 2025-04-05 01:31:46,750 log 4456 87528 Unauthorized: /api/auth/login/
WARNING 2025-04-05 01:31:46,750 basehttp 4456 87528 "POST /api/auth/login/ HTTP/1.1" 401 31
INFO 2025-04-05 01:35:06,501 autoreload 4456 85268 C:\WISENTIA_Q\wisentia\wisentia_backend\users\views.py changed, reloading.
INFO 2025-04-05 01:35:07,405 autoreload 11080 84572 Watching for file changes with StatReloader
INFO 2025-04-05 01:35:41,258 autoreload 11080 84572 C:\WISENTIA_Q\wisentia\wisentia_backend\users\views.py changed, reloading.
INFO 2025-04-05 01:35:42,134 autoreload 42704 85508 Watching for file changes with StatReloader
WARNING 2025-04-05 01:40:52,330 log 42704 88636 Unauthorized: /api/auth/login/
WARNING 2025-04-05 01:40:52,331 basehttp 42704 88636 "POST /api/auth/login/ HTTP/1.1" 401 31
INFO 2025-04-05 01:40:58,131 basehttp 42704 80148 "POST /api/auth/login/ HTTP/1.1" 200 483
ERROR 2025-04-05 01:41:00,191 middleware 42704 71740 API Error: type object 'User' has no attribute 'pk'
ERROR 2025-04-05 01:41:00,191 middleware 42704 71740 Traceback (most recent call last):
  File "C:\WISENTIA_Q\wisentia\venv\Lib\site-packages\django\core\handlers\base.py", line 197, in _get_response
    response = wrapped_callback(request, *callback_args, **callback_kwargs)
               ^^^^^^^^^^^^^^^^^^^^^^^^^^^^^^^^^^^^^^^^^^^^^^^^^^^^^^^^^^^^
  File "C:\WISENTIA_Q\wisentia\venv\Lib\site-packages\django\views\decorators\csrf.py", line 65, in _view_wrapper
    return view_func(request, *args, **kwargs)
           ^^^^^^^^^^^^^^^^^^^^^^^^^^^^^^^^^^^
  File "C:\WISENTIA_Q\wisentia\venv\Lib\site-packages\django\views\generic\base.py", line 104, in view
    return self.dispatch(request, *args, **kwargs)
           ^^^^^^^^^^^^^^^^^^^^^^^^^^^^^^^^^^^^^^^
  File "C:\WISENTIA_Q\wisentia\venv\Lib\site-packages\rest_framework\views.py", line 515, in dispatch
    response = self.handle_exception(exc)
               ^^^^^^^^^^^^^^^^^^^^^^^^^^
  File "C:\WISENTIA_Q\wisentia\venv\Lib\site-packages\rest_framework\views.py", line 475, in handle_exception
    self.raise_uncaught_exception(exc)
  File "C:\WISENTIA_Q\wisentia\venv\Lib\site-packages\rest_framework\views.py", line 486, in raise_uncaught_exception
    raise exc
  File "C:\WISENTIA_Q\wisentia\venv\Lib\site-packages\rest_framework\views.py", line 503, in dispatch
    self.initial(request, *args, **kwargs)
  File "C:\WISENTIA_Q\wisentia\venv\Lib\site-packages\rest_framework\views.py", line 422, in initial
    self.check_throttles(request)
  File "C:\WISENTIA_Q\wisentia\venv\Lib\site-packages\rest_framework\views.py", line 365, in check_throttles
    if not throttle.allow_request(request, self):
           ^^^^^^^^^^^^^^^^^^^^^^^^^^^^^^^^^^^^^
  File "C:\WISENTIA_Q\wisentia\venv\Lib\site-packages\rest_framework\throttling.py", line 119, in allow_request
    self.key = self.get_cache_key(request, view)
               ^^^^^^^^^^^^^^^^^^^^^^^^^^^^^^^^^
  File "C:\WISENTIA_Q\wisentia\venv\Lib\site-packages\rest_framework\throttling.py", line 195, in get_cache_key
    ident = request.user.pk
            ^^^^^^^^^^^^^^^
AttributeError: type object 'User' has no attribute 'pk'

ERROR 2025-04-05 01:41:00,192 log 42704 71740 Internal Server Error: /api/courses/
ERROR 2025-04-05 01:41:00,192 basehttp 42704 71740 "GET /api/courses/ HTTP/1.1" 500 2326
ERROR 2025-04-05 01:41:08,313 middleware 42704 82080 API Error: No results.  Previous SQL was not a query.
ERROR 2025-04-05 01:41:08,313 middleware 42704 82080 Traceback (most recent call last):
  File "C:\WISENTIA_Q\wisentia\venv\Lib\site-packages\django\db\utils.py", line 98, in inner
    return func(*args, **kwargs)
           ^^^^^^^^^^^^^^^^^^^^^
  File "C:\WISENTIA_Q\wisentia\venv\Lib\site-packages\mssql\base.py", line 712, in fetchone
    row = self.cursor.fetchone()
          ^^^^^^^^^^^^^^^^^^^^^^
pyodbc.ProgrammingError: No results.  Previous SQL was not a query.

The above exception was the direct cause of the following exception:

Traceback (most recent call last):
  File "C:\WISENTIA_Q\wisentia\venv\Lib\site-packages\django\core\handlers\base.py", line 197, in _get_response
    response = wrapped_callback(request, *callback_args, **callback_kwargs)
               ^^^^^^^^^^^^^^^^^^^^^^^^^^^^^^^^^^^^^^^^^^^^^^^^^^^^^^^^^^^^
  File "C:\WISENTIA_Q\wisentia\venv\Lib\site-packages\django\views\decorators\csrf.py", line 65, in _view_wrapper
    return view_func(request, *args, **kwargs)
           ^^^^^^^^^^^^^^^^^^^^^^^^^^^^^^^^^^^
  File "C:\WISENTIA_Q\wisentia\venv\Lib\site-packages\django\views\generic\base.py", line 104, in view
    return self.dispatch(request, *args, **kwargs)
           ^^^^^^^^^^^^^^^^^^^^^^^^^^^^^^^^^^^^^^^
  File "C:\WISENTIA_Q\wisentia\venv\Lib\site-packages\rest_framework\views.py", line 515, in dispatch
    response = self.handle_exception(exc)
               ^^^^^^^^^^^^^^^^^^^^^^^^^^
  File "C:\WISENTIA_Q\wisentia\venv\Lib\site-packages\rest_framework\views.py", line 475, in handle_exception
    self.raise_uncaught_exception(exc)
  File "C:\WISENTIA_Q\wisentia\venv\Lib\site-packages\rest_framework\views.py", line 486, in raise_uncaught_exception
    raise exc
  File "C:\WISENTIA_Q\wisentia\venv\Lib\site-packages\rest_framework\views.py", line 512, in dispatch
    response = handler(request, *args, **kwargs)
               ^^^^^^^^^^^^^^^^^^^^^^^^^^^^^^^^^
  File "C:\WISENTIA_Q\wisentia\venv\Lib\site-packages\rest_framework\decorators.py", line 50, in handler
    return func(*args, **kwargs)
           ^^^^^^^^^^^^^^^^^^^^^
  File "C:\WISENTIA_Q\wisentia\wisentia_backend\users\views.py", line 129, in register
    user_id = cursor.fetchone()[0]
              ^^^^^^^^^^^^^^^^^
  File "C:\WISENTIA_Q\wisentia\venv\Lib\site-packages\django\db\utils.py", line 97, in inner
    with self:
  File "C:\WISENTIA_Q\wisentia\venv\Lib\site-packages\django\db\utils.py", line 91, in __exit__
    raise dj_exc_value.with_traceback(traceback) from exc_value
  File "C:\WISENTIA_Q\wisentia\venv\Lib\site-packages\django\db\utils.py", line 98, in inner
    return func(*args, **kwargs)
           ^^^^^^^^^^^^^^^^^^^^^
  File "C:\WISENTIA_Q\wisentia\venv\Lib\site-packages\mssql\base.py", line 712, in fetchone
    row = self.cursor.fetchone()
          ^^^^^^^^^^^^^^^^^^^^^^
django.db.utils.ProgrammingError: No results.  Previous SQL was not a query.

ERROR 2025-04-05 01:41:08,314 log 42704 82080 Internal Server Error: /api/auth/register/
ERROR 2025-04-05 01:41:08,314 basehttp 42704 82080 "POST /api/auth/register/ HTTP/1.1" 500 3138
ERROR 2025-04-05 01:41:29,771 middleware 42704 89692 API Error: ('23000', "[23000] [Microsoft][ODBC Driver 17 for SQL Server][SQL Server]Violation of UNIQUE KEY constraint 'UQ__Users__6D19B83B36C6A55E'. Cannot insert duplicate key in object 'dbo.Users'. The duplicate key value is (). (2627) (SQLExecDirectW); [23000] [Microsoft][ODBC Driver 17 for SQL Server][SQL Server]The statement has been terminated. (3621)")
ERROR 2025-04-05 01:41:29,771 middleware 42704 89692 Traceback (most recent call last):
  File "C:\WISENTIA_Q\wisentia\venv\Lib\site-packages\django\db\backends\utils.py", line 105, in _execute
    return self.cursor.execute(sql, params)
           ^^^^^^^^^^^^^^^^^^^^^^^^^^^^^^^^
  File "C:\WISENTIA_Q\wisentia\venv\Lib\site-packages\mssql\base.py", line 677, in execute
    return self.cursor.execute(sql, params)
           ^^^^^^^^^^^^^^^^^^^^^^^^^^^^^^^^
pyodbc.IntegrityError: ('23000', "[23000] [Microsoft][ODBC Driver 17 for SQL Server][SQL Server]Violation of UNIQUE KEY constraint 'UQ__Users__6D19B83B36C6A55E'. Cannot insert duplicate key in object 'dbo.Users'. The duplicate key value is (). (2627) (SQLExecDirectW); [23000] [Microsoft][ODBC Driver 17 for SQL Server][SQL Server]The statement has been terminated. (3621)")

The above exception was the direct cause of the following exception:

Traceback (most recent call last):
  File "C:\WISENTIA_Q\wisentia\venv\Lib\site-packages\django\core\handlers\base.py", line 197, in _get_response
    response = wrapped_callback(request, *callback_args, **callback_kwargs)
               ^^^^^^^^^^^^^^^^^^^^^^^^^^^^^^^^^^^^^^^^^^^^^^^^^^^^^^^^^^^^
  File "C:\WISENTIA_Q\wisentia\venv\Lib\site-packages\django\views\decorators\csrf.py", line 65, in _view_wrapper
    return view_func(request, *args, **kwargs)
           ^^^^^^^^^^^^^^^^^^^^^^^^^^^^^^^^^^^
  File "C:\WISENTIA_Q\wisentia\venv\Lib\site-packages\django\views\generic\base.py", line 104, in view
    return self.dispatch(request, *args, **kwargs)
           ^^^^^^^^^^^^^^^^^^^^^^^^^^^^^^^^^^^^^^^
  File "C:\WISENTIA_Q\wisentia\venv\Lib\site-packages\rest_framework\views.py", line 515, in dispatch
    response = self.handle_exception(exc)
               ^^^^^^^^^^^^^^^^^^^^^^^^^^
  File "C:\WISENTIA_Q\wisentia\venv\Lib\site-packages\rest_framework\views.py", line 475, in handle_exception
    self.raise_uncaught_exception(exc)
  File "C:\WISENTIA_Q\wisentia\venv\Lib\site-packages\rest_framework\views.py", line 486, in raise_uncaught_exception
    raise exc
  File "C:\WISENTIA_Q\wisentia\venv\Lib\site-packages\rest_framework\views.py", line 512, in dispatch
    response = handler(request, *args, **kwargs)
               ^^^^^^^^^^^^^^^^^^^^^^^^^^^^^^^^^
  File "C:\WISENTIA_Q\wisentia\venv\Lib\site-packages\rest_framework\decorators.py", line 50, in handler
    return func(*args, **kwargs)
           ^^^^^^^^^^^^^^^^^^^^^
  File "C:\WISENTIA_Q\wisentia\wisentia_backend\users\views.py", line 121, in register
    cursor.execute("""
  File "C:\WISENTIA_Q\wisentia\venv\Lib\site-packages\django\db\backends\utils.py", line 122, in execute
    return super().execute(sql, params)
           ^^^^^^^^^^^^^^^^^^^^^^^^^^^^
  File "C:\WISENTIA_Q\wisentia\venv\Lib\site-packages\django\db\backends\utils.py", line 79, in execute
    return self._execute_with_wrappers(
           ^^^^^^^^^^^^^^^^^^^^^^^^^^^^
  File "C:\WISENTIA_Q\wisentia\venv\Lib\site-packages\django\db\backends\utils.py", line 92, in _execute_with_wrappers
    return executor(sql, params, many, context)
           ^^^^^^^^^^^^^^^^^^^^^^^^^^^^^^^^^^^^
  File "C:\WISENTIA_Q\wisentia\venv\Lib\site-packages\django\db\backends\utils.py", line 100, in _execute
    with self.db.wrap_database_errors:
  File "C:\WISENTIA_Q\wisentia\venv\Lib\site-packages\django\db\utils.py", line 91, in __exit__
    raise dj_exc_value.with_traceback(traceback) from exc_value
  File "C:\WISENTIA_Q\wisentia\venv\Lib\site-packages\django\db\backends\utils.py", line 105, in _execute
    return self.cursor.execute(sql, params)
           ^^^^^^^^^^^^^^^^^^^^^^^^^^^^^^^^
  File "C:\WISENTIA_Q\wisentia\venv\Lib\site-packages\mssql\base.py", line 677, in execute
    return self.cursor.execute(sql, params)
           ^^^^^^^^^^^^^^^^^^^^^^^^^^^^^^^^
django.db.utils.IntegrityError: ('23000', "[23000] [Microsoft][ODBC Driver 17 for SQL Server][SQL Server]Violation of UNIQUE KEY constraint 'UQ__Users__6D19B83B36C6A55E'. Cannot insert duplicate key in object 'dbo.Users'. The duplicate key value is (). (2627) (SQLExecDirectW); [23000] [Microsoft][ODBC Driver 17 for SQL Server][SQL Server]The statement has been terminated. (3621)")

ERROR 2025-04-05 01:41:29,772 log 42704 89692 Internal Server Error: /api/auth/register/
ERROR 2025-04-05 01:41:29,772 basehttp 42704 89692 "POST /api/auth/register/ HTTP/1.1" 500 4803
INFO 2025-04-05 01:41:38,459 basehttp 42704 85076 "POST /api/auth/login/ HTTP/1.1" 200 483
ERROR 2025-04-05 01:41:40,499 middleware 42704 80432 API Error: type object 'User' has no attribute 'pk'
ERROR 2025-04-05 01:41:40,499 middleware 42704 80432 Traceback (most recent call last):
  File "C:\WISENTIA_Q\wisentia\venv\Lib\site-packages\django\core\handlers\base.py", line 197, in _get_response
    response = wrapped_callback(request, *callback_args, **callback_kwargs)
               ^^^^^^^^^^^^^^^^^^^^^^^^^^^^^^^^^^^^^^^^^^^^^^^^^^^^^^^^^^^^
  File "C:\WISENTIA_Q\wisentia\venv\Lib\site-packages\django\views\decorators\csrf.py", line 65, in _view_wrapper
    return view_func(request, *args, **kwargs)
           ^^^^^^^^^^^^^^^^^^^^^^^^^^^^^^^^^^^
  File "C:\WISENTIA_Q\wisentia\venv\Lib\site-packages\django\views\generic\base.py", line 104, in view
    return self.dispatch(request, *args, **kwargs)
           ^^^^^^^^^^^^^^^^^^^^^^^^^^^^^^^^^^^^^^^
  File "C:\WISENTIA_Q\wisentia\venv\Lib\site-packages\rest_framework\views.py", line 515, in dispatch
    response = self.handle_exception(exc)
               ^^^^^^^^^^^^^^^^^^^^^^^^^^
  File "C:\WISENTIA_Q\wisentia\venv\Lib\site-packages\rest_framework\views.py", line 475, in handle_exception
    self.raise_uncaught_exception(exc)
  File "C:\WISENTIA_Q\wisentia\venv\Lib\site-packages\rest_framework\views.py", line 486, in raise_uncaught_exception
    raise exc
  File "C:\WISENTIA_Q\wisentia\venv\Lib\site-packages\rest_framework\views.py", line 503, in dispatch
    self.initial(request, *args, **kwargs)
  File "C:\WISENTIA_Q\wisentia\venv\Lib\site-packages\rest_framework\views.py", line 422, in initial
    self.check_throttles(request)
  File "C:\WISENTIA_Q\wisentia\venv\Lib\site-packages\rest_framework\views.py", line 365, in check_throttles
    if not throttle.allow_request(request, self):
           ^^^^^^^^^^^^^^^^^^^^^^^^^^^^^^^^^^^^^
  File "C:\WISENTIA_Q\wisentia\venv\Lib\site-packages\rest_framework\throttling.py", line 119, in allow_request
    self.key = self.get_cache_key(request, view)
               ^^^^^^^^^^^^^^^^^^^^^^^^^^^^^^^^^
  File "C:\WISENTIA_Q\wisentia\venv\Lib\site-packages\rest_framework\throttling.py", line 195, in get_cache_key
    ident = request.user.pk
            ^^^^^^^^^^^^^^^
AttributeError: type object 'User' has no attribute 'pk'

ERROR 2025-04-05 01:41:40,500 log 42704 80432 Internal Server Error: /api/courses/
ERROR 2025-04-05 01:41:40,500 basehttp 42704 80432 "GET /api/courses/ HTTP/1.1" 500 2326
WARNING 2025-04-05 01:41:41,778 log 42704 90080 Unauthorized: /api/auth/login/
WARNING 2025-04-05 01:41:41,778 basehttp 42704 90080 "POST /api/auth/login/ HTTP/1.1" 401 31
INFO 2025-04-05 01:43:34,272 basehttp 42704 84884 "GET /swagger/ HTTP/1.1" 200 2215
INFO 2025-04-05 01:43:34,470 basehttp 42704 84884 "GET /static/drf-yasg/style.css HTTP/1.1" 200 1047
INFO 2025-04-05 01:43:34,475 basehttp 42704 83180 "GET /static/drf-yasg/swagger-ui-dist/swagger-ui.css HTTP/1.1" 200 145206
INFO 2025-04-05 01:43:34,482 basehttp 42704 83180 "GET /static/drf-yasg/swagger-ui-dist/swagger-ui-standalone-preset.js HTTP/1.1" 200 322863
INFO 2025-04-05 01:43:34,487 basehttp 42704 83180 "GET /static/drf-yasg/insQ.min.js HTTP/1.1" 200 2093
INFO 2025-04-05 01:43:34,502 basehttp 42704 84884 "GET /static/drf-yasg/swagger-ui-dist/swagger-ui-bundle.js HTTP/1.1" 200 1046583
INFO 2025-04-05 01:43:34,505 basehttp 42704 83180 "GET /static/drf-yasg/immutable.min.js HTTP/1.1" 200 56904
INFO 2025-04-05 01:43:34,505 basehttp 42704 84884 "GET /static/drf-yasg/swagger-ui-init.js HTTP/1.1" 200 15480
INFO 2025-04-05 01:43:34,696 basehttp 42704 84884 "GET /swagger/?format=openapi HTTP/1.1" 200 27889
INFO 2025-04-05 01:43:35,637 basehttp 42704 84884 "GET /static/drf-yasg/swagger-ui-dist/favicon-32x32.png HTTP/1.1" 200 628
INFO 2025-04-05 01:45:55,910 autoreload 42704 85508 C:\WISENTIA_Q\wisentia\wisentia_backend\users\throttling.py changed, reloading.
INFO 2025-04-05 01:45:56,794 autoreload 64860 86212 Watching for file changes with StatReloader
INFO 2025-04-05 01:46:07,762 autoreload 89576 89400 Watching for file changes with StatReloader
ERROR 2025-04-05 01:46:39,909 middleware 89576 82112 API Error: ('23000', "[23000] [Microsoft][ODBC Driver 17 for SQL Server][SQL Server]Violation of UNIQUE KEY constraint 'UQ__Users__6D19B83B36C6A55E'. Cannot insert duplicate key in object 'dbo.Users'. The duplicate key value is (). (2627) (SQLExecDirectW); [23000] [Microsoft][ODBC Driver 17 for SQL Server][SQL Server]The statement has been terminated. (3621)")
ERROR 2025-04-05 01:46:39,910 middleware 89576 82112 Traceback (most recent call last):
  File "C:\WISENTIA_Q\wisentia\venv\Lib\site-packages\django\db\backends\utils.py", line 105, in _execute
    return self.cursor.execute(sql, params)
           ^^^^^^^^^^^^^^^^^^^^^^^^^^^^^^^^
  File "C:\WISENTIA_Q\wisentia\venv\Lib\site-packages\mssql\base.py", line 677, in execute
    return self.cursor.execute(sql, params)
           ^^^^^^^^^^^^^^^^^^^^^^^^^^^^^^^^
pyodbc.IntegrityError: ('23000', "[23000] [Microsoft][ODBC Driver 17 for SQL Server][SQL Server]Violation of UNIQUE KEY constraint 'UQ__Users__6D19B83B36C6A55E'. Cannot insert duplicate key in object 'dbo.Users'. The duplicate key value is (). (2627) (SQLExecDirectW); [23000] [Microsoft][ODBC Driver 17 for SQL Server][SQL Server]The statement has been terminated. (3621)")

The above exception was the direct cause of the following exception:

Traceback (most recent call last):
  File "C:\WISENTIA_Q\wisentia\venv\Lib\site-packages\django\core\handlers\base.py", line 197, in _get_response
    response = wrapped_callback(request, *callback_args, **callback_kwargs)
               ^^^^^^^^^^^^^^^^^^^^^^^^^^^^^^^^^^^^^^^^^^^^^^^^^^^^^^^^^^^^
  File "C:\WISENTIA_Q\wisentia\venv\Lib\site-packages\django\views\decorators\csrf.py", line 65, in _view_wrapper
    return view_func(request, *args, **kwargs)
           ^^^^^^^^^^^^^^^^^^^^^^^^^^^^^^^^^^^
  File "C:\WISENTIA_Q\wisentia\venv\Lib\site-packages\django\views\generic\base.py", line 104, in view
    return self.dispatch(request, *args, **kwargs)
           ^^^^^^^^^^^^^^^^^^^^^^^^^^^^^^^^^^^^^^^
  File "C:\WISENTIA_Q\wisentia\venv\Lib\site-packages\rest_framework\views.py", line 515, in dispatch
    response = self.handle_exception(exc)
               ^^^^^^^^^^^^^^^^^^^^^^^^^^
  File "C:\WISENTIA_Q\wisentia\venv\Lib\site-packages\rest_framework\views.py", line 475, in handle_exception
    self.raise_uncaught_exception(exc)
  File "C:\WISENTIA_Q\wisentia\venv\Lib\site-packages\rest_framework\views.py", line 486, in raise_uncaught_exception
    raise exc
  File "C:\WISENTIA_Q\wisentia\venv\Lib\site-packages\rest_framework\views.py", line 512, in dispatch
    response = handler(request, *args, **kwargs)
               ^^^^^^^^^^^^^^^^^^^^^^^^^^^^^^^^^
  File "C:\WISENTIA_Q\wisentia\venv\Lib\site-packages\rest_framework\decorators.py", line 50, in handler
    return func(*args, **kwargs)
           ^^^^^^^^^^^^^^^^^^^^^
  File "C:\WISENTIA_Q\wisentia\wisentia_backend\users\views.py", line 121, in register
    cursor.execute("""
  File "C:\WISENTIA_Q\wisentia\venv\Lib\site-packages\django\db\backends\utils.py", line 122, in execute
    return super().execute(sql, params)
           ^^^^^^^^^^^^^^^^^^^^^^^^^^^^
  File "C:\WISENTIA_Q\wisentia\venv\Lib\site-packages\django\db\backends\utils.py", line 79, in execute
    return self._execute_with_wrappers(
           ^^^^^^^^^^^^^^^^^^^^^^^^^^^^
  File "C:\WISENTIA_Q\wisentia\venv\Lib\site-packages\django\db\backends\utils.py", line 92, in _execute_with_wrappers
    return executor(sql, params, many, context)
           ^^^^^^^^^^^^^^^^^^^^^^^^^^^^^^^^^^^^
  File "C:\WISENTIA_Q\wisentia\venv\Lib\site-packages\django\db\backends\utils.py", line 100, in _execute
    with self.db.wrap_database_errors:
  File "C:\WISENTIA_Q\wisentia\venv\Lib\site-packages\django\db\utils.py", line 91, in __exit__
    raise dj_exc_value.with_traceback(traceback) from exc_value
  File "C:\WISENTIA_Q\wisentia\venv\Lib\site-packages\django\db\backends\utils.py", line 105, in _execute
    return self.cursor.execute(sql, params)
           ^^^^^^^^^^^^^^^^^^^^^^^^^^^^^^^^
  File "C:\WISENTIA_Q\wisentia\venv\Lib\site-packages\mssql\base.py", line 677, in execute
    return self.cursor.execute(sql, params)
           ^^^^^^^^^^^^^^^^^^^^^^^^^^^^^^^^
django.db.utils.IntegrityError: ('23000', "[23000] [Microsoft][ODBC Driver 17 for SQL Server][SQL Server]Violation of UNIQUE KEY constraint 'UQ__Users__6D19B83B36C6A55E'. Cannot insert duplicate key in object 'dbo.Users'. The duplicate key value is (). (2627) (SQLExecDirectW); [23000] [Microsoft][ODBC Driver 17 for SQL Server][SQL Server]The statement has been terminated. (3621)")

ERROR 2025-04-05 01:46:39,911 log 89576 82112 Internal Server Error: /api/auth/register/
ERROR 2025-04-05 01:46:39,911 basehttp 89576 82112 "POST /api/auth/register/ HTTP/1.1" 500 4803
WARNING 2025-04-05 01:46:48,961 log 89576 73132 Unauthorized: /api/auth/login/
WARNING 2025-04-05 01:46:48,961 basehttp 89576 73132 "POST /api/auth/login/ HTTP/1.1" 401 31
WARNING 2025-04-05 01:46:58,338 log 89576 84128 Unauthorized: /api/auth/login/
WARNING 2025-04-05 01:46:58,338 basehttp 89576 84128 "POST /api/auth/login/ HTTP/1.1" 401 31
INFO 2025-04-06 03:28:06,601 autoreload 84380 100032 Watching for file changes with StatReloader
INFO 2025-04-06 03:28:29,903 basehttp 84380 21312 "OPTIONS /api/auth/login/ HTTP/1.1" 200 0
WARNING 2025-04-06 03:28:29,961 log 84380 21312 Unauthorized: /api/auth/login/
WARNING 2025-04-06 03:28:29,963 basehttp 84380 21312 "POST /api/auth/login/ HTTP/1.1" 401 31
WARNING 2025-04-06 03:28:44,305 log 84380 21312 Unauthorized: /api/auth/login/
WARNING 2025-04-06 03:28:44,306 basehttp 84380 21312 "POST /api/auth/login/ HTTP/1.1" 401 31
WARNING 2025-04-06 03:31:02,963 log 84380 21312 Unauthorized: /api/auth/login/
WARNING 2025-04-06 03:31:02,964 basehttp 84380 21312 "POST /api/auth/login/ HTTP/1.1" 401 31
INFO 2025-04-06 03:32:01,810 basehttp 84380 21312 "OPTIONS /api/auth/register/ HTTP/1.1" 200 0
ERROR 2025-04-06 03:32:01,969 middleware 84380 21312 API Error: ('23000', "[23000] [Microsoft][ODBC Driver 17 for SQL Server][SQL Server]Violation of UNIQUE KEY constraint 'UQ__Users__6D19B83B36C6A55E'. Cannot insert duplicate key in object 'dbo.Users'. The duplicate key value is (). (2627) (SQLExecDirectW); [23000] [Microsoft][ODBC Driver 17 for SQL Server][SQL Server]The statement has been terminated. (3621)")
ERROR 2025-04-06 03:32:01,970 middleware 84380 21312 Traceback (most recent call last):
  File "C:\WISENTIA_Q\wisentia\venv\Lib\site-packages\django\db\backends\utils.py", line 105, in _execute
    return self.cursor.execute(sql, params)
           ^^^^^^^^^^^^^^^^^^^^^^^^^^^^^^^^
  File "C:\WISENTIA_Q\wisentia\venv\Lib\site-packages\mssql\base.py", line 677, in execute
    return self.cursor.execute(sql, params)
           ^^^^^^^^^^^^^^^^^^^^^^^^^^^^^^^^
pyodbc.IntegrityError: ('23000', "[23000] [Microsoft][ODBC Driver 17 for SQL Server][SQL Server]Violation of UNIQUE KEY constraint 'UQ__Users__6D19B83B36C6A55E'. Cannot insert duplicate key in object 'dbo.Users'. The duplicate key value is (). (2627) (SQLExecDirectW); [23000] [Microsoft][ODBC Driver 17 for SQL Server][SQL Server]The statement has been terminated. (3621)")

The above exception was the direct cause of the following exception:

Traceback (most recent call last):
  File "C:\WISENTIA_Q\wisentia\venv\Lib\site-packages\django\core\handlers\base.py", line 197, in _get_response
    response = wrapped_callback(request, *callback_args, **callback_kwargs)
               ^^^^^^^^^^^^^^^^^^^^^^^^^^^^^^^^^^^^^^^^^^^^^^^^^^^^^^^^^^^^
  File "C:\WISENTIA_Q\wisentia\venv\Lib\site-packages\django\views\decorators\csrf.py", line 65, in _view_wrapper
    return view_func(request, *args, **kwargs)
           ^^^^^^^^^^^^^^^^^^^^^^^^^^^^^^^^^^^
  File "C:\WISENTIA_Q\wisentia\venv\Lib\site-packages\django\views\generic\base.py", line 104, in view
    return self.dispatch(request, *args, **kwargs)
           ^^^^^^^^^^^^^^^^^^^^^^^^^^^^^^^^^^^^^^^
  File "C:\WISENTIA_Q\wisentia\venv\Lib\site-packages\rest_framework\views.py", line 515, in dispatch
    response = self.handle_exception(exc)
               ^^^^^^^^^^^^^^^^^^^^^^^^^^
  File "C:\WISENTIA_Q\wisentia\venv\Lib\site-packages\rest_framework\views.py", line 475, in handle_exception
    self.raise_uncaught_exception(exc)
  File "C:\WISENTIA_Q\wisentia\venv\Lib\site-packages\rest_framework\views.py", line 486, in raise_uncaught_exception
    raise exc
  File "C:\WISENTIA_Q\wisentia\venv\Lib\site-packages\rest_framework\views.py", line 512, in dispatch
    response = handler(request, *args, **kwargs)
               ^^^^^^^^^^^^^^^^^^^^^^^^^^^^^^^^^
  File "C:\WISENTIA_Q\wisentia\venv\Lib\site-packages\rest_framework\decorators.py", line 50, in handler
    return func(*args, **kwargs)
           ^^^^^^^^^^^^^^^^^^^^^
  File "C:\WISENTIA_Q\wisentia\wisentia_backend\users\views.py", line 121, in register
    cursor.execute("""
  File "C:\WISENTIA_Q\wisentia\venv\Lib\site-packages\django\db\backends\utils.py", line 122, in execute
    return super().execute(sql, params)
           ^^^^^^^^^^^^^^^^^^^^^^^^^^^^
  File "C:\WISENTIA_Q\wisentia\venv\Lib\site-packages\django\db\backends\utils.py", line 79, in execute
    return self._execute_with_wrappers(
           ^^^^^^^^^^^^^^^^^^^^^^^^^^^^
  File "C:\WISENTIA_Q\wisentia\venv\Lib\site-packages\django\db\backends\utils.py", line 92, in _execute_with_wrappers
    return executor(sql, params, many, context)
           ^^^^^^^^^^^^^^^^^^^^^^^^^^^^^^^^^^^^
  File "C:\WISENTIA_Q\wisentia\venv\Lib\site-packages\django\db\backends\utils.py", line 100, in _execute
    with self.db.wrap_database_errors:
  File "C:\WISENTIA_Q\wisentia\venv\Lib\site-packages\django\db\utils.py", line 91, in __exit__
    raise dj_exc_value.with_traceback(traceback) from exc_value
  File "C:\WISENTIA_Q\wisentia\venv\Lib\site-packages\django\db\backends\utils.py", line 105, in _execute
    return self.cursor.execute(sql, params)
           ^^^^^^^^^^^^^^^^^^^^^^^^^^^^^^^^
  File "C:\WISENTIA_Q\wisentia\venv\Lib\site-packages\mssql\base.py", line 677, in execute
    return self.cursor.execute(sql, params)
           ^^^^^^^^^^^^^^^^^^^^^^^^^^^^^^^^
django.db.utils.IntegrityError: ('23000', "[23000] [Microsoft][ODBC Driver 17 for SQL Server][SQL Server]Violation of UNIQUE KEY constraint 'UQ__Users__6D19B83B36C6A55E'. Cannot insert duplicate key in object 'dbo.Users'. The duplicate key value is (). (2627) (SQLExecDirectW); [23000] [Microsoft][ODBC Driver 17 for SQL Server][SQL Server]The statement has been terminated. (3621)")

ERROR 2025-04-06 03:32:01,971 log 84380 21312 Internal Server Error: /api/auth/register/
ERROR 2025-04-06 03:32:01,972 basehttp 84380 21312 "POST /api/auth/register/ HTTP/1.1" 500 4803
ERROR 2025-04-06 03:37:24,186 middleware 84380 94820 API Error: No results.  Previous SQL was not a query.
ERROR 2025-04-06 03:37:24,186 middleware 84380 94820 Traceback (most recent call last):
  File "C:\WISENTIA_Q\wisentia\venv\Lib\site-packages\django\db\utils.py", line 98, in inner
    return func(*args, **kwargs)
           ^^^^^^^^^^^^^^^^^^^^^
  File "C:\WISENTIA_Q\wisentia\venv\Lib\site-packages\mssql\base.py", line 712, in fetchone
    row = self.cursor.fetchone()
          ^^^^^^^^^^^^^^^^^^^^^^
pyodbc.ProgrammingError: No results.  Previous SQL was not a query.

The above exception was the direct cause of the following exception:

Traceback (most recent call last):
  File "C:\WISENTIA_Q\wisentia\venv\Lib\site-packages\django\core\handlers\base.py", line 197, in _get_response
    response = wrapped_callback(request, *callback_args, **callback_kwargs)
               ^^^^^^^^^^^^^^^^^^^^^^^^^^^^^^^^^^^^^^^^^^^^^^^^^^^^^^^^^^^^
  File "C:\WISENTIA_Q\wisentia\venv\Lib\site-packages\django\views\decorators\csrf.py", line 65, in _view_wrapper
    return view_func(request, *args, **kwargs)
           ^^^^^^^^^^^^^^^^^^^^^^^^^^^^^^^^^^^
  File "C:\WISENTIA_Q\wisentia\venv\Lib\site-packages\django\views\generic\base.py", line 104, in view
    return self.dispatch(request, *args, **kwargs)
           ^^^^^^^^^^^^^^^^^^^^^^^^^^^^^^^^^^^^^^^
  File "C:\WISENTIA_Q\wisentia\venv\Lib\site-packages\rest_framework\views.py", line 515, in dispatch
    response = self.handle_exception(exc)
               ^^^^^^^^^^^^^^^^^^^^^^^^^^
  File "C:\WISENTIA_Q\wisentia\venv\Lib\site-packages\rest_framework\views.py", line 475, in handle_exception
    self.raise_uncaught_exception(exc)
  File "C:\WISENTIA_Q\wisentia\venv\Lib\site-packages\rest_framework\views.py", line 486, in raise_uncaught_exception
    raise exc
  File "C:\WISENTIA_Q\wisentia\venv\Lib\site-packages\rest_framework\views.py", line 512, in dispatch
    response = handler(request, *args, **kwargs)
               ^^^^^^^^^^^^^^^^^^^^^^^^^^^^^^^^^
  File "C:\WISENTIA_Q\wisentia\venv\Lib\site-packages\rest_framework\decorators.py", line 50, in handler
    return func(*args, **kwargs)
           ^^^^^^^^^^^^^^^^^^^^^
  File "C:\WISENTIA_Q\wisentia\wisentia_backend\users\views.py", line 129, in register
    user_id = cursor.fetchone()[0]
              ^^^^^^^^^^^^^^^^^
  File "C:\WISENTIA_Q\wisentia\venv\Lib\site-packages\django\db\utils.py", line 97, in inner
    with self:
  File "C:\WISENTIA_Q\wisentia\venv\Lib\site-packages\django\db\utils.py", line 91, in __exit__
    raise dj_exc_value.with_traceback(traceback) from exc_value
  File "C:\WISENTIA_Q\wisentia\venv\Lib\site-packages\django\db\utils.py", line 98, in inner
    return func(*args, **kwargs)
           ^^^^^^^^^^^^^^^^^^^^^
  File "C:\WISENTIA_Q\wisentia\venv\Lib\site-packages\mssql\base.py", line 712, in fetchone
    row = self.cursor.fetchone()
          ^^^^^^^^^^^^^^^^^^^^^^
django.db.utils.ProgrammingError: No results.  Previous SQL was not a query.

ERROR 2025-04-06 03:37:24,187 log 84380 94820 Internal Server Error: /api/auth/register/
ERROR 2025-04-06 03:37:24,188 basehttp 84380 94820 "POST /api/auth/register/ HTTP/1.1" 500 3138
WARNING 2025-04-06 03:41:57,158 log 84380 94820 Bad Request: /api/auth/register/
WARNING 2025-04-06 03:41:57,159 basehttp 84380 94820 "POST /api/auth/register/ HTTP/1.1" 400 44
INFO 2025-04-06 03:42:06,872 basehttp 84380 94820 "POST /api/auth/login/ HTTP/1.1" 200 492
INFO 2025-04-06 03:42:10,376 basehttp 84380 94820 "POST /api/auth/login/ HTTP/1.1" 200 492
INFO 2025-04-06 03:42:24,500 basehttp 84380 94820 "POST /api/auth/login/ HTTP/1.1" 200 492
INFO 2025-04-06 03:42:25,872 basehttp 84380 94820 "POST /api/auth/login/ HTTP/1.1" 200 492
INFO 2025-04-06 03:42:27,101 basehttp 84380 94820 "POST /api/auth/login/ HTTP/1.1" 200 492
INFO 2025-04-06 03:44:05,332 basehttp 84380 94820 "POST /api/auth/login/ HTTP/1.1" 200 492
INFO 2025-04-06 03:44:06,738 basehttp 84380 94820 "POST /api/auth/login/ HTTP/1.1" 200 492
INFO 2025-04-06 03:44:29,800 basehttp 84380 94820 "POST /api/auth/login/ HTTP/1.1" 200 492
INFO 2025-04-06 03:44:37,264 basehttp 84380 94820 "POST /api/auth/login/ HTTP/1.1" 200 492
INFO 2025-04-06 03:44:38,338 basehttp 84380 94820 "POST /api/auth/login/ HTTP/1.1" 200 492
INFO 2025-04-06 03:44:39,814 basehttp 84380 94820 "POST /api/auth/login/ HTTP/1.1" 200 492
INFO 2025-04-06 03:45:53,743 basehttp 84380 94820 "POST /api/auth/login/ HTTP/1.1" 200 492
INFO 2025-04-06 03:45:54,786 basehttp 84380 94820 "POST /api/auth/login/ HTTP/1.1" 200 492
INFO 2025-04-06 03:46:57,928 basehttp 84380 94820 "POST /api/auth/login/ HTTP/1.1" 200 492
INFO 2025-04-06 03:46:59,389 basehttp 84380 94820 "POST /api/auth/login/ HTTP/1.1" 200 492
INFO 2025-04-06 03:47:00,205 basehttp 84380 94820 "POST /api/auth/login/ HTTP/1.1" 200 492
INFO 2025-04-06 03:47:01,401 basehttp 84380 94820 "POST /api/auth/login/ HTTP/1.1" 200 492
INFO 2025-04-06 03:47:02,150 basehttp 84380 94820 "POST /api/auth/login/ HTTP/1.1" 200 492
INFO 2025-04-06 03:47:44,589 basehttp 84380 94820 "POST /api/auth/login/ HTTP/1.1" 200 492
INFO 2025-04-06 03:47:54,749 basehttp 84380 94820 "POST /api/auth/login/ HTTP/1.1" 200 492
INFO 2025-04-06 03:48:55,269 basehttp 84380 94820 "POST /api/auth/login/ HTTP/1.1" 200 492
INFO 2025-04-06 03:52:25,798 basehttp 84380 94820 "POST /api/auth/login/ HTTP/1.1" 200 492
INFO 2025-04-06 03:52:27,039 basehttp 84380 94820 "POST /api/auth/login/ HTTP/1.1" 200 492
INFO 2025-04-08 14:33:30,744 autoreload 131048 138888 Watching for file changes with StatReloader
INFO 2025-04-08 14:36:02,902 autoreload 136556 130620 Watching for file changes with StatReloader
INFO 2025-04-08 14:36:39,196 basehttp 136556 130192 "OPTIONS /api/auth/login/ HTTP/1.1" 200 0
INFO 2025-04-08 14:36:39,255 basehttp 136556 130192 "POST /api/auth/login/ HTTP/1.1" 200 492
INFO 2025-04-08 14:36:47,483 basehttp 136556 130192 "POST /api/auth/login/ HTTP/1.1" 200 492
INFO 2025-04-08 14:36:53,255 basehttp 136556 130192 "POST /api/auth/login/ HTTP/1.1" 200 492
INFO 2025-04-08 14:36:56,111 basehttp 136556 130192 "POST /api/auth/login/ HTTP/1.1" 200 492
INFO 2025-04-08 14:36:57,067 basehttp 136556 130192 "POST /api/auth/login/ HTTP/1.1" 200 492
WARNING 2025-04-08 14:37:40,028 log 136556 130192 Unauthorized: /api/auth/login/
WARNING 2025-04-08 14:37:40,029 basehttp 136556 130192 "POST /api/auth/login/ HTTP/1.1" 401 31
INFO 2025-04-08 14:49:27,211 autoreload 133896 126100 Watching for file changes with StatReloader
INFO 2025-04-08 14:55:13,743 basehttp 133896 126092 "OPTIONS /api/auth/login/ HTTP/1.1" 200 0
INFO 2025-04-08 14:55:13,785 basehttp 133896 126092 "POST /api/auth/login/ HTTP/1.1" 200 492
INFO 2025-04-08 14:55:24,351 basehttp 133896 126092 "POST /api/auth/login/ HTTP/1.1" 200 492
INFO 2025-04-08 14:55:25,909 basehttp 133896 126092 "POST /api/auth/login/ HTTP/1.1" 200 492
INFO 2025-04-08 14:55:55,536 basehttp 133896 126092 "POST /api/auth/login/ HTTP/1.1" 200 492
WARNING 2025-04-08 15:01:33,431 log 133896 118956 Not Found: /api
WARNING 2025-04-08 15:01:33,432 basehttp 133896 118956 "GET /api HTTP/1.1" 404 4107
WARNING 2025-04-08 15:01:33,861 log 133896 118956 Not Found: /favicon.ico
WARNING 2025-04-08 15:01:33,862 basehttp 133896 118956 "GET /favicon.ico HTTP/1.1" 404 4131
INFO 2025-04-08 15:03:44,596 basehttp 133896 48980 "POST /api/auth/login/ HTTP/1.1" 200 492
INFO 2025-04-08 15:24:48,458 basehttp 133896 138156 "OPTIONS /api/auth/register/ HTTP/1.1" 200 0
ERROR 2025-04-08 15:24:48,603 middleware 133896 138156 API Error: ('23000', "[23000] [Microsoft][ODBC Driver 17 for SQL Server][SQL Server]Violation of UNIQUE KEY constraint 'UQ__Users__6D19B83B36C6A55E'. Cannot insert duplicate key in object 'dbo.Users'. The duplicate key value is (). (2627) (SQLExecDirectW); [23000] [Microsoft][ODBC Driver 17 for SQL Server][SQL Server]The statement has been terminated. (3621)")
ERROR 2025-04-08 15:24:48,603 middleware 133896 138156 Traceback (most recent call last):
  File "C:\WISENTIA_Q\wisentia\venv\Lib\site-packages\django\db\backends\utils.py", line 105, in _execute
    return self.cursor.execute(sql, params)
           ^^^^^^^^^^^^^^^^^^^^^^^^^^^^^^^^
  File "C:\WISENTIA_Q\wisentia\venv\Lib\site-packages\mssql\base.py", line 677, in execute
    return self.cursor.execute(sql, params)
           ^^^^^^^^^^^^^^^^^^^^^^^^^^^^^^^^
pyodbc.IntegrityError: ('23000', "[23000] [Microsoft][ODBC Driver 17 for SQL Server][SQL Server]Violation of UNIQUE KEY constraint 'UQ__Users__6D19B83B36C6A55E'. Cannot insert duplicate key in object 'dbo.Users'. The duplicate key value is (). (2627) (SQLExecDirectW); [23000] [Microsoft][ODBC Driver 17 for SQL Server][SQL Server]The statement has been terminated. (3621)")

The above exception was the direct cause of the following exception:

Traceback (most recent call last):
  File "C:\WISENTIA_Q\wisentia\venv\Lib\site-packages\django\core\handlers\base.py", line 197, in _get_response
    response = wrapped_callback(request, *callback_args, **callback_kwargs)
               ^^^^^^^^^^^^^^^^^^^^^^^^^^^^^^^^^^^^^^^^^^^^^^^^^^^^^^^^^^^^
  File "C:\WISENTIA_Q\wisentia\venv\Lib\site-packages\django\views\decorators\csrf.py", line 65, in _view_wrapper
    return view_func(request, *args, **kwargs)
           ^^^^^^^^^^^^^^^^^^^^^^^^^^^^^^^^^^^
  File "C:\WISENTIA_Q\wisentia\venv\Lib\site-packages\django\views\generic\base.py", line 104, in view
    return self.dispatch(request, *args, **kwargs)
           ^^^^^^^^^^^^^^^^^^^^^^^^^^^^^^^^^^^^^^^
  File "C:\WISENTIA_Q\wisentia\venv\Lib\site-packages\rest_framework\views.py", line 515, in dispatch
    response = self.handle_exception(exc)
               ^^^^^^^^^^^^^^^^^^^^^^^^^^
  File "C:\WISENTIA_Q\wisentia\venv\Lib\site-packages\rest_framework\views.py", line 475, in handle_exception
    self.raise_uncaught_exception(exc)
  File "C:\WISENTIA_Q\wisentia\venv\Lib\site-packages\rest_framework\views.py", line 486, in raise_uncaught_exception
    raise exc
  File "C:\WISENTIA_Q\wisentia\venv\Lib\site-packages\rest_framework\views.py", line 512, in dispatch
    response = handler(request, *args, **kwargs)
               ^^^^^^^^^^^^^^^^^^^^^^^^^^^^^^^^^
  File "C:\WISENTIA_Q\wisentia\venv\Lib\site-packages\rest_framework\decorators.py", line 50, in handler
    return func(*args, **kwargs)
           ^^^^^^^^^^^^^^^^^^^^^
  File "C:\WISENTIA_Q\wisentia\wisentia_backend\users\views.py", line 121, in register
    cursor.execute("""
  File "C:\WISENTIA_Q\wisentia\venv\Lib\site-packages\django\db\backends\utils.py", line 122, in execute
    return super().execute(sql, params)
           ^^^^^^^^^^^^^^^^^^^^^^^^^^^^
  File "C:\WISENTIA_Q\wisentia\venv\Lib\site-packages\django\db\backends\utils.py", line 79, in execute
    return self._execute_with_wrappers(
           ^^^^^^^^^^^^^^^^^^^^^^^^^^^^
  File "C:\WISENTIA_Q\wisentia\venv\Lib\site-packages\django\db\backends\utils.py", line 92, in _execute_with_wrappers
    return executor(sql, params, many, context)
           ^^^^^^^^^^^^^^^^^^^^^^^^^^^^^^^^^^^^
  File "C:\WISENTIA_Q\wisentia\venv\Lib\site-packages\django\db\backends\utils.py", line 100, in _execute
    with self.db.wrap_database_errors:
  File "C:\WISENTIA_Q\wisentia\venv\Lib\site-packages\django\db\utils.py", line 91, in __exit__
    raise dj_exc_value.with_traceback(traceback) from exc_value
  File "C:\WISENTIA_Q\wisentia\venv\Lib\site-packages\django\db\backends\utils.py", line 105, in _execute
    return self.cursor.execute(sql, params)
           ^^^^^^^^^^^^^^^^^^^^^^^^^^^^^^^^
  File "C:\WISENTIA_Q\wisentia\venv\Lib\site-packages\mssql\base.py", line 677, in execute
    return self.cursor.execute(sql, params)
           ^^^^^^^^^^^^^^^^^^^^^^^^^^^^^^^^
django.db.utils.IntegrityError: ('23000', "[23000] [Microsoft][ODBC Driver 17 for SQL Server][SQL Server]Violation of UNIQUE KEY constraint 'UQ__Users__6D19B83B36C6A55E'. Cannot insert duplicate key in object 'dbo.Users'. The duplicate key value is (). (2627) (SQLExecDirectW); [23000] [Microsoft][ODBC Driver 17 for SQL Server][SQL Server]The statement has been terminated. (3621)")

ERROR 2025-04-08 15:24:48,604 log 133896 138156 Internal Server Error: /api/auth/register/
ERROR 2025-04-08 15:24:48,605 basehttp 133896 138156 "POST /api/auth/register/ HTTP/1.1" 500 4803
INFO 2025-04-08 15:25:56,115 basehttp 133896 138156 "POST /api/auth/login/ HTTP/1.1" 200 492
INFO 2025-04-08 18:26:22,851 basehttp 133896 132204 "OPTIONS /api/auth/login/ HTTP/1.1" 200 0
INFO 2025-04-08 18:26:22,892 basehttp 133896 132204 "POST /api/auth/login/ HTTP/1.1" 200 492
INFO 2025-04-08 18:29:54,451 basehttp 133896 132204 "POST /api/auth/login/ HTTP/1.1" 200 492
INFO 2025-04-08 18:29:56,123 basehttp 133896 132204 "POST /api/auth/login/ HTTP/1.1" 200 492
INFO 2025-04-08 18:29:57,273 basehttp 133896 132204 "POST /api/auth/login/ HTTP/1.1" 200 492
INFO 2025-04-08 18:29:58,463 basehttp 133896 132204 "POST /api/auth/login/ HTTP/1.1" 200 492
INFO 2025-04-08 18:29:59,249 basehttp 133896 132204 "POST /api/auth/login/ HTTP/1.1" 200 492
INFO 2025-04-08 18:30:08,618 basehttp 133896 132204 "POST /api/auth/login/ HTTP/1.1" 200 492
INFO 2025-04-08 18:31:27,123 basehttp 133896 132204 "POST /api/auth/login/ HTTP/1.1" 200 492
INFO 2025-04-08 18:32:46,110 basehttp 133896 132204 "OPTIONS /api/auth/register/ HTTP/1.1" 200 0
WARNING 2025-04-08 18:32:46,121 log 133896 132204 Bad Request: /api/auth/register/
WARNING 2025-04-08 18:32:46,123 basehttp 133896 132204 "POST /api/auth/register/ HTTP/1.1" 400 44
ERROR 2025-04-08 18:32:52,235 middleware 133896 132204 API Error: ('23000', "[23000] [Microsoft][ODBC Driver 17 for SQL Server][SQL Server]Violation of UNIQUE KEY constraint 'UQ__Users__6D19B83B36C6A55E'. Cannot insert duplicate key in object 'dbo.Users'. The duplicate key value is (). (2627) (SQLExecDirectW); [23000] [Microsoft][ODBC Driver 17 for SQL Server][SQL Server]The statement has been terminated. (3621)")
ERROR 2025-04-08 18:32:52,236 middleware 133896 132204 Traceback (most recent call last):
  File "C:\WISENTIA_Q\wisentia\venv\Lib\site-packages\django\db\backends\utils.py", line 105, in _execute
    return self.cursor.execute(sql, params)
           ^^^^^^^^^^^^^^^^^^^^^^^^^^^^^^^^
  File "C:\WISENTIA_Q\wisentia\venv\Lib\site-packages\mssql\base.py", line 677, in execute
    return self.cursor.execute(sql, params)
           ^^^^^^^^^^^^^^^^^^^^^^^^^^^^^^^^
pyodbc.IntegrityError: ('23000', "[23000] [Microsoft][ODBC Driver 17 for SQL Server][SQL Server]Violation of UNIQUE KEY constraint 'UQ__Users__6D19B83B36C6A55E'. Cannot insert duplicate key in object 'dbo.Users'. The duplicate key value is (). (2627) (SQLExecDirectW); [23000] [Microsoft][ODBC Driver 17 for SQL Server][SQL Server]The statement has been terminated. (3621)")

The above exception was the direct cause of the following exception:

Traceback (most recent call last):
  File "C:\WISENTIA_Q\wisentia\venv\Lib\site-packages\django\core\handlers\base.py", line 197, in _get_response
    response = wrapped_callback(request, *callback_args, **callback_kwargs)
               ^^^^^^^^^^^^^^^^^^^^^^^^^^^^^^^^^^^^^^^^^^^^^^^^^^^^^^^^^^^^
  File "C:\WISENTIA_Q\wisentia\venv\Lib\site-packages\django\views\decorators\csrf.py", line 65, in _view_wrapper
    return view_func(request, *args, **kwargs)
           ^^^^^^^^^^^^^^^^^^^^^^^^^^^^^^^^^^^
  File "C:\WISENTIA_Q\wisentia\venv\Lib\site-packages\django\views\generic\base.py", line 104, in view
    return self.dispatch(request, *args, **kwargs)
           ^^^^^^^^^^^^^^^^^^^^^^^^^^^^^^^^^^^^^^^
  File "C:\WISENTIA_Q\wisentia\venv\Lib\site-packages\rest_framework\views.py", line 515, in dispatch
    response = self.handle_exception(exc)
               ^^^^^^^^^^^^^^^^^^^^^^^^^^
  File "C:\WISENTIA_Q\wisentia\venv\Lib\site-packages\rest_framework\views.py", line 475, in handle_exception
    self.raise_uncaught_exception(exc)
  File "C:\WISENTIA_Q\wisentia\venv\Lib\site-packages\rest_framework\views.py", line 486, in raise_uncaught_exception
    raise exc
  File "C:\WISENTIA_Q\wisentia\venv\Lib\site-packages\rest_framework\views.py", line 512, in dispatch
    response = handler(request, *args, **kwargs)
               ^^^^^^^^^^^^^^^^^^^^^^^^^^^^^^^^^
  File "C:\WISENTIA_Q\wisentia\venv\Lib\site-packages\rest_framework\decorators.py", line 50, in handler
    return func(*args, **kwargs)
           ^^^^^^^^^^^^^^^^^^^^^
  File "C:\WISENTIA_Q\wisentia\wisentia_backend\users\views.py", line 121, in register
    cursor.execute("""
  File "C:\WISENTIA_Q\wisentia\venv\Lib\site-packages\django\db\backends\utils.py", line 122, in execute
    return super().execute(sql, params)
           ^^^^^^^^^^^^^^^^^^^^^^^^^^^^
  File "C:\WISENTIA_Q\wisentia\venv\Lib\site-packages\django\db\backends\utils.py", line 79, in execute
    return self._execute_with_wrappers(
           ^^^^^^^^^^^^^^^^^^^^^^^^^^^^
  File "C:\WISENTIA_Q\wisentia\venv\Lib\site-packages\django\db\backends\utils.py", line 92, in _execute_with_wrappers
    return executor(sql, params, many, context)
           ^^^^^^^^^^^^^^^^^^^^^^^^^^^^^^^^^^^^
  File "C:\WISENTIA_Q\wisentia\venv\Lib\site-packages\django\db\backends\utils.py", line 100, in _execute
    with self.db.wrap_database_errors:
  File "C:\WISENTIA_Q\wisentia\venv\Lib\site-packages\django\db\utils.py", line 91, in __exit__
    raise dj_exc_value.with_traceback(traceback) from exc_value
  File "C:\WISENTIA_Q\wisentia\venv\Lib\site-packages\django\db\backends\utils.py", line 105, in _execute
    return self.cursor.execute(sql, params)
           ^^^^^^^^^^^^^^^^^^^^^^^^^^^^^^^^
  File "C:\WISENTIA_Q\wisentia\venv\Lib\site-packages\mssql\base.py", line 677, in execute
    return self.cursor.execute(sql, params)
           ^^^^^^^^^^^^^^^^^^^^^^^^^^^^^^^^
django.db.utils.IntegrityError: ('23000', "[23000] [Microsoft][ODBC Driver 17 for SQL Server][SQL Server]Violation of UNIQUE KEY constraint 'UQ__Users__6D19B83B36C6A55E'. Cannot insert duplicate key in object 'dbo.Users'. The duplicate key value is (). (2627) (SQLExecDirectW); [23000] [Microsoft][ODBC Driver 17 for SQL Server][SQL Server]The statement has been terminated. (3621)")

ERROR 2025-04-08 18:32:52,238 log 133896 132204 Internal Server Error: /api/auth/register/
ERROR 2025-04-08 18:32:52,238 basehttp 133896 132204 "POST /api/auth/register/ HTTP/1.1" 500 4803
ERROR 2025-04-08 18:34:07,425 middleware 133896 132204 API Error: ('23000', "[23000] [Microsoft][ODBC Driver 17 for SQL Server][SQL Server]Violation of UNIQUE KEY constraint 'UQ__Users__6D19B83B36C6A55E'. Cannot insert duplicate key in object 'dbo.Users'. The duplicate key value is (). (2627) (SQLExecDirectW); [23000] [Microsoft][ODBC Driver 17 for SQL Server][SQL Server]The statement has been terminated. (3621)")
ERROR 2025-04-08 18:34:07,425 middleware 133896 132204 Traceback (most recent call last):
  File "C:\WISENTIA_Q\wisentia\venv\Lib\site-packages\django\db\backends\utils.py", line 105, in _execute
    return self.cursor.execute(sql, params)
           ^^^^^^^^^^^^^^^^^^^^^^^^^^^^^^^^
  File "C:\WISENTIA_Q\wisentia\venv\Lib\site-packages\mssql\base.py", line 677, in execute
    return self.cursor.execute(sql, params)
           ^^^^^^^^^^^^^^^^^^^^^^^^^^^^^^^^
pyodbc.IntegrityError: ('23000', "[23000] [Microsoft][ODBC Driver 17 for SQL Server][SQL Server]Violation of UNIQUE KEY constraint 'UQ__Users__6D19B83B36C6A55E'. Cannot insert duplicate key in object 'dbo.Users'. The duplicate key value is (). (2627) (SQLExecDirectW); [23000] [Microsoft][ODBC Driver 17 for SQL Server][SQL Server]The statement has been terminated. (3621)")

The above exception was the direct cause of the following exception:

Traceback (most recent call last):
  File "C:\WISENTIA_Q\wisentia\venv\Lib\site-packages\django\core\handlers\base.py", line 197, in _get_response
    response = wrapped_callback(request, *callback_args, **callback_kwargs)
               ^^^^^^^^^^^^^^^^^^^^^^^^^^^^^^^^^^^^^^^^^^^^^^^^^^^^^^^^^^^^
  File "C:\WISENTIA_Q\wisentia\venv\Lib\site-packages\django\views\decorators\csrf.py", line 65, in _view_wrapper
    return view_func(request, *args, **kwargs)
           ^^^^^^^^^^^^^^^^^^^^^^^^^^^^^^^^^^^
  File "C:\WISENTIA_Q\wisentia\venv\Lib\site-packages\django\views\generic\base.py", line 104, in view
    return self.dispatch(request, *args, **kwargs)
           ^^^^^^^^^^^^^^^^^^^^^^^^^^^^^^^^^^^^^^^
  File "C:\WISENTIA_Q\wisentia\venv\Lib\site-packages\rest_framework\views.py", line 515, in dispatch
    response = self.handle_exception(exc)
               ^^^^^^^^^^^^^^^^^^^^^^^^^^
  File "C:\WISENTIA_Q\wisentia\venv\Lib\site-packages\rest_framework\views.py", line 475, in handle_exception
    self.raise_uncaught_exception(exc)
  File "C:\WISENTIA_Q\wisentia\venv\Lib\site-packages\rest_framework\views.py", line 486, in raise_uncaught_exception
    raise exc
  File "C:\WISENTIA_Q\wisentia\venv\Lib\site-packages\rest_framework\views.py", line 512, in dispatch
    response = handler(request, *args, **kwargs)
               ^^^^^^^^^^^^^^^^^^^^^^^^^^^^^^^^^
  File "C:\WISENTIA_Q\wisentia\venv\Lib\site-packages\rest_framework\decorators.py", line 50, in handler
    return func(*args, **kwargs)
           ^^^^^^^^^^^^^^^^^^^^^
  File "C:\WISENTIA_Q\wisentia\wisentia_backend\users\views.py", line 121, in register
    cursor.execute("""
  File "C:\WISENTIA_Q\wisentia\venv\Lib\site-packages\django\db\backends\utils.py", line 122, in execute
    return super().execute(sql, params)
           ^^^^^^^^^^^^^^^^^^^^^^^^^^^^
  File "C:\WISENTIA_Q\wisentia\venv\Lib\site-packages\django\db\backends\utils.py", line 79, in execute
    return self._execute_with_wrappers(
           ^^^^^^^^^^^^^^^^^^^^^^^^^^^^
  File "C:\WISENTIA_Q\wisentia\venv\Lib\site-packages\django\db\backends\utils.py", line 92, in _execute_with_wrappers
    return executor(sql, params, many, context)
           ^^^^^^^^^^^^^^^^^^^^^^^^^^^^^^^^^^^^
  File "C:\WISENTIA_Q\wisentia\venv\Lib\site-packages\django\db\backends\utils.py", line 100, in _execute
    with self.db.wrap_database_errors:
  File "C:\WISENTIA_Q\wisentia\venv\Lib\site-packages\django\db\utils.py", line 91, in __exit__
    raise dj_exc_value.with_traceback(traceback) from exc_value
  File "C:\WISENTIA_Q\wisentia\venv\Lib\site-packages\django\db\backends\utils.py", line 105, in _execute
    return self.cursor.execute(sql, params)
           ^^^^^^^^^^^^^^^^^^^^^^^^^^^^^^^^
  File "C:\WISENTIA_Q\wisentia\venv\Lib\site-packages\mssql\base.py", line 677, in execute
    return self.cursor.execute(sql, params)
           ^^^^^^^^^^^^^^^^^^^^^^^^^^^^^^^^
django.db.utils.IntegrityError: ('23000', "[23000] [Microsoft][ODBC Driver 17 for SQL Server][SQL Server]Violation of UNIQUE KEY constraint 'UQ__Users__6D19B83B36C6A55E'. Cannot insert duplicate key in object 'dbo.Users'. The duplicate key value is (). (2627) (SQLExecDirectW); [23000] [Microsoft][ODBC Driver 17 for SQL Server][SQL Server]The statement has been terminated. (3621)")

ERROR 2025-04-08 18:34:07,426 log 133896 132204 Internal Server Error: /api/auth/register/
ERROR 2025-04-08 18:34:07,427 basehttp 133896 132204 "POST /api/auth/register/ HTTP/1.1" 500 4803
WARNING 2025-04-08 18:39:23,864 log 133896 130188 Bad Request: /api/auth/register/
WARNING 2025-04-08 18:39:23,865 basehttp 133896 130188 "POST /api/auth/register/ HTTP/1.1" 400 44
ERROR 2025-04-08 18:40:20,289 middleware 133896 130188 API Error: ('23000', "[23000] [Microsoft][ODBC Driver 17 for SQL Server][SQL Server]Violation of UNIQUE KEY constraint 'UQ__Users__6D19B83B36C6A55E'. Cannot insert duplicate key in object 'dbo.Users'. The duplicate key value is (). (2627) (SQLExecDirectW); [23000] [Microsoft][ODBC Driver 17 for SQL Server][SQL Server]The statement has been terminated. (3621)")
ERROR 2025-04-08 18:40:20,289 middleware 133896 130188 Traceback (most recent call last):
  File "C:\WISENTIA_Q\wisentia\venv\Lib\site-packages\django\db\backends\utils.py", line 105, in _execute
    return self.cursor.execute(sql, params)
           ^^^^^^^^^^^^^^^^^^^^^^^^^^^^^^^^
  File "C:\WISENTIA_Q\wisentia\venv\Lib\site-packages\mssql\base.py", line 677, in execute
    return self.cursor.execute(sql, params)
           ^^^^^^^^^^^^^^^^^^^^^^^^^^^^^^^^
pyodbc.IntegrityError: ('23000', "[23000] [Microsoft][ODBC Driver 17 for SQL Server][SQL Server]Violation of UNIQUE KEY constraint 'UQ__Users__6D19B83B36C6A55E'. Cannot insert duplicate key in object 'dbo.Users'. The duplicate key value is (). (2627) (SQLExecDirectW); [23000] [Microsoft][ODBC Driver 17 for SQL Server][SQL Server]The statement has been terminated. (3621)")

The above exception was the direct cause of the following exception:

Traceback (most recent call last):
  File "C:\WISENTIA_Q\wisentia\venv\Lib\site-packages\django\core\handlers\base.py", line 197, in _get_response
    response = wrapped_callback(request, *callback_args, **callback_kwargs)
               ^^^^^^^^^^^^^^^^^^^^^^^^^^^^^^^^^^^^^^^^^^^^^^^^^^^^^^^^^^^^
  File "C:\WISENTIA_Q\wisentia\venv\Lib\site-packages\django\views\decorators\csrf.py", line 65, in _view_wrapper
    return view_func(request, *args, **kwargs)
           ^^^^^^^^^^^^^^^^^^^^^^^^^^^^^^^^^^^
  File "C:\WISENTIA_Q\wisentia\venv\Lib\site-packages\django\views\generic\base.py", line 104, in view
    return self.dispatch(request, *args, **kwargs)
           ^^^^^^^^^^^^^^^^^^^^^^^^^^^^^^^^^^^^^^^
  File "C:\WISENTIA_Q\wisentia\venv\Lib\site-packages\rest_framework\views.py", line 515, in dispatch
    response = self.handle_exception(exc)
               ^^^^^^^^^^^^^^^^^^^^^^^^^^
  File "C:\WISENTIA_Q\wisentia\venv\Lib\site-packages\rest_framework\views.py", line 475, in handle_exception
    self.raise_uncaught_exception(exc)
  File "C:\WISENTIA_Q\wisentia\venv\Lib\site-packages\rest_framework\views.py", line 486, in raise_uncaught_exception
    raise exc
  File "C:\WISENTIA_Q\wisentia\venv\Lib\site-packages\rest_framework\views.py", line 512, in dispatch
    response = handler(request, *args, **kwargs)
               ^^^^^^^^^^^^^^^^^^^^^^^^^^^^^^^^^
  File "C:\WISENTIA_Q\wisentia\venv\Lib\site-packages\rest_framework\decorators.py", line 50, in handler
    return func(*args, **kwargs)
           ^^^^^^^^^^^^^^^^^^^^^
  File "C:\WISENTIA_Q\wisentia\wisentia_backend\users\views.py", line 121, in register
    cursor.execute("""
  File "C:\WISENTIA_Q\wisentia\venv\Lib\site-packages\django\db\backends\utils.py", line 122, in execute
    return super().execute(sql, params)
           ^^^^^^^^^^^^^^^^^^^^^^^^^^^^
  File "C:\WISENTIA_Q\wisentia\venv\Lib\site-packages\django\db\backends\utils.py", line 79, in execute
    return self._execute_with_wrappers(
           ^^^^^^^^^^^^^^^^^^^^^^^^^^^^
  File "C:\WISENTIA_Q\wisentia\venv\Lib\site-packages\django\db\backends\utils.py", line 92, in _execute_with_wrappers
    return executor(sql, params, many, context)
           ^^^^^^^^^^^^^^^^^^^^^^^^^^^^^^^^^^^^
  File "C:\WISENTIA_Q\wisentia\venv\Lib\site-packages\django\db\backends\utils.py", line 100, in _execute
    with self.db.wrap_database_errors:
  File "C:\WISENTIA_Q\wisentia\venv\Lib\site-packages\django\db\utils.py", line 91, in __exit__
    raise dj_exc_value.with_traceback(traceback) from exc_value
  File "C:\WISENTIA_Q\wisentia\venv\Lib\site-packages\django\db\backends\utils.py", line 105, in _execute
    return self.cursor.execute(sql, params)
           ^^^^^^^^^^^^^^^^^^^^^^^^^^^^^^^^
  File "C:\WISENTIA_Q\wisentia\venv\Lib\site-packages\mssql\base.py", line 677, in execute
    return self.cursor.execute(sql, params)
           ^^^^^^^^^^^^^^^^^^^^^^^^^^^^^^^^
django.db.utils.IntegrityError: ('23000', "[23000] [Microsoft][ODBC Driver 17 for SQL Server][SQL Server]Violation of UNIQUE KEY constraint 'UQ__Users__6D19B83B36C6A55E'. Cannot insert duplicate key in object 'dbo.Users'. The duplicate key value is (). (2627) (SQLExecDirectW); [23000] [Microsoft][ODBC Driver 17 for SQL Server][SQL Server]The statement has been terminated. (3621)")

ERROR 2025-04-08 18:40:20,290 log 133896 130188 Internal Server Error: /api/auth/register/
ERROR 2025-04-08 18:40:20,290 basehttp 133896 130188 "POST /api/auth/register/ HTTP/1.1" 500 4803
ERROR 2025-04-08 18:40:23,409 middleware 133896 130188 API Error: ('23000', "[23000] [Microsoft][ODBC Driver 17 for SQL Server][SQL Server]Violation of UNIQUE KEY constraint 'UQ__Users__6D19B83B36C6A55E'. Cannot insert duplicate key in object 'dbo.Users'. The duplicate key value is (). (2627) (SQLExecDirectW); [23000] [Microsoft][ODBC Driver 17 for SQL Server][SQL Server]The statement has been terminated. (3621)")
ERROR 2025-04-08 18:40:23,409 middleware 133896 130188 Traceback (most recent call last):
  File "C:\WISENTIA_Q\wisentia\venv\Lib\site-packages\django\db\backends\utils.py", line 105, in _execute
    return self.cursor.execute(sql, params)
           ^^^^^^^^^^^^^^^^^^^^^^^^^^^^^^^^
  File "C:\WISENTIA_Q\wisentia\venv\Lib\site-packages\mssql\base.py", line 677, in execute
    return self.cursor.execute(sql, params)
           ^^^^^^^^^^^^^^^^^^^^^^^^^^^^^^^^
pyodbc.IntegrityError: ('23000', "[23000] [Microsoft][ODBC Driver 17 for SQL Server][SQL Server]Violation of UNIQUE KEY constraint 'UQ__Users__6D19B83B36C6A55E'. Cannot insert duplicate key in object 'dbo.Users'. The duplicate key value is (). (2627) (SQLExecDirectW); [23000] [Microsoft][ODBC Driver 17 for SQL Server][SQL Server]The statement has been terminated. (3621)")

The above exception was the direct cause of the following exception:

Traceback (most recent call last):
  File "C:\WISENTIA_Q\wisentia\venv\Lib\site-packages\django\core\handlers\base.py", line 197, in _get_response
    response = wrapped_callback(request, *callback_args, **callback_kwargs)
               ^^^^^^^^^^^^^^^^^^^^^^^^^^^^^^^^^^^^^^^^^^^^^^^^^^^^^^^^^^^^
  File "C:\WISENTIA_Q\wisentia\venv\Lib\site-packages\django\views\decorators\csrf.py", line 65, in _view_wrapper
    return view_func(request, *args, **kwargs)
           ^^^^^^^^^^^^^^^^^^^^^^^^^^^^^^^^^^^
  File "C:\WISENTIA_Q\wisentia\venv\Lib\site-packages\django\views\generic\base.py", line 104, in view
    return self.dispatch(request, *args, **kwargs)
           ^^^^^^^^^^^^^^^^^^^^^^^^^^^^^^^^^^^^^^^
  File "C:\WISENTIA_Q\wisentia\venv\Lib\site-packages\rest_framework\views.py", line 515, in dispatch
    response = self.handle_exception(exc)
               ^^^^^^^^^^^^^^^^^^^^^^^^^^
  File "C:\WISENTIA_Q\wisentia\venv\Lib\site-packages\rest_framework\views.py", line 475, in handle_exception
    self.raise_uncaught_exception(exc)
  File "C:\WISENTIA_Q\wisentia\venv\Lib\site-packages\rest_framework\views.py", line 486, in raise_uncaught_exception
    raise exc
  File "C:\WISENTIA_Q\wisentia\venv\Lib\site-packages\rest_framework\views.py", line 512, in dispatch
    response = handler(request, *args, **kwargs)
               ^^^^^^^^^^^^^^^^^^^^^^^^^^^^^^^^^
  File "C:\WISENTIA_Q\wisentia\venv\Lib\site-packages\rest_framework\decorators.py", line 50, in handler
    return func(*args, **kwargs)
           ^^^^^^^^^^^^^^^^^^^^^
  File "C:\WISENTIA_Q\wisentia\wisentia_backend\users\views.py", line 121, in register
    cursor.execute("""
  File "C:\WISENTIA_Q\wisentia\venv\Lib\site-packages\django\db\backends\utils.py", line 122, in execute
    return super().execute(sql, params)
           ^^^^^^^^^^^^^^^^^^^^^^^^^^^^
  File "C:\WISENTIA_Q\wisentia\venv\Lib\site-packages\django\db\backends\utils.py", line 79, in execute
    return self._execute_with_wrappers(
           ^^^^^^^^^^^^^^^^^^^^^^^^^^^^
  File "C:\WISENTIA_Q\wisentia\venv\Lib\site-packages\django\db\backends\utils.py", line 92, in _execute_with_wrappers
    return executor(sql, params, many, context)
           ^^^^^^^^^^^^^^^^^^^^^^^^^^^^^^^^^^^^
  File "C:\WISENTIA_Q\wisentia\venv\Lib\site-packages\django\db\backends\utils.py", line 100, in _execute
    with self.db.wrap_database_errors:
  File "C:\WISENTIA_Q\wisentia\venv\Lib\site-packages\django\db\utils.py", line 91, in __exit__
    raise dj_exc_value.with_traceback(traceback) from exc_value
  File "C:\WISENTIA_Q\wisentia\venv\Lib\site-packages\django\db\backends\utils.py", line 105, in _execute
    return self.cursor.execute(sql, params)
           ^^^^^^^^^^^^^^^^^^^^^^^^^^^^^^^^
  File "C:\WISENTIA_Q\wisentia\venv\Lib\site-packages\mssql\base.py", line 677, in execute
    return self.cursor.execute(sql, params)
           ^^^^^^^^^^^^^^^^^^^^^^^^^^^^^^^^
django.db.utils.IntegrityError: ('23000', "[23000] [Microsoft][ODBC Driver 17 for SQL Server][SQL Server]Violation of UNIQUE KEY constraint 'UQ__Users__6D19B83B36C6A55E'. Cannot insert duplicate key in object 'dbo.Users'. The duplicate key value is (). (2627) (SQLExecDirectW); [23000] [Microsoft][ODBC Driver 17 for SQL Server][SQL Server]The statement has been terminated. (3621)")

ERROR 2025-04-08 18:40:23,410 log 133896 130188 Internal Server Error: /api/auth/register/
ERROR 2025-04-08 18:40:23,410 basehttp 133896 130188 "POST /api/auth/register/ HTTP/1.1" 500 4803
ERROR 2025-04-08 18:40:28,341 middleware 133896 130188 API Error: ('23000', "[23000] [Microsoft][ODBC Driver 17 for SQL Server][SQL Server]Violation of UNIQUE KEY constraint 'UQ__Users__6D19B83B36C6A55E'. Cannot insert duplicate key in object 'dbo.Users'. The duplicate key value is (). (2627) (SQLExecDirectW); [23000] [Microsoft][ODBC Driver 17 for SQL Server][SQL Server]The statement has been terminated. (3621)")
ERROR 2025-04-08 18:40:28,341 middleware 133896 130188 Traceback (most recent call last):
  File "C:\WISENTIA_Q\wisentia\venv\Lib\site-packages\django\db\backends\utils.py", line 105, in _execute
    return self.cursor.execute(sql, params)
           ^^^^^^^^^^^^^^^^^^^^^^^^^^^^^^^^
  File "C:\WISENTIA_Q\wisentia\venv\Lib\site-packages\mssql\base.py", line 677, in execute
    return self.cursor.execute(sql, params)
           ^^^^^^^^^^^^^^^^^^^^^^^^^^^^^^^^
pyodbc.IntegrityError: ('23000', "[23000] [Microsoft][ODBC Driver 17 for SQL Server][SQL Server]Violation of UNIQUE KEY constraint 'UQ__Users__6D19B83B36C6A55E'. Cannot insert duplicate key in object 'dbo.Users'. The duplicate key value is (). (2627) (SQLExecDirectW); [23000] [Microsoft][ODBC Driver 17 for SQL Server][SQL Server]The statement has been terminated. (3621)")

The above exception was the direct cause of the following exception:

Traceback (most recent call last):
  File "C:\WISENTIA_Q\wisentia\venv\Lib\site-packages\django\core\handlers\base.py", line 197, in _get_response
    response = wrapped_callback(request, *callback_args, **callback_kwargs)
               ^^^^^^^^^^^^^^^^^^^^^^^^^^^^^^^^^^^^^^^^^^^^^^^^^^^^^^^^^^^^
  File "C:\WISENTIA_Q\wisentia\venv\Lib\site-packages\django\views\decorators\csrf.py", line 65, in _view_wrapper
    return view_func(request, *args, **kwargs)
           ^^^^^^^^^^^^^^^^^^^^^^^^^^^^^^^^^^^
  File "C:\WISENTIA_Q\wisentia\venv\Lib\site-packages\django\views\generic\base.py", line 104, in view
    return self.dispatch(request, *args, **kwargs)
           ^^^^^^^^^^^^^^^^^^^^^^^^^^^^^^^^^^^^^^^
  File "C:\WISENTIA_Q\wisentia\venv\Lib\site-packages\rest_framework\views.py", line 515, in dispatch
    response = self.handle_exception(exc)
               ^^^^^^^^^^^^^^^^^^^^^^^^^^
  File "C:\WISENTIA_Q\wisentia\venv\Lib\site-packages\rest_framework\views.py", line 475, in handle_exception
    self.raise_uncaught_exception(exc)
  File "C:\WISENTIA_Q\wisentia\venv\Lib\site-packages\rest_framework\views.py", line 486, in raise_uncaught_exception
    raise exc
  File "C:\WISENTIA_Q\wisentia\venv\Lib\site-packages\rest_framework\views.py", line 512, in dispatch
    response = handler(request, *args, **kwargs)
               ^^^^^^^^^^^^^^^^^^^^^^^^^^^^^^^^^
  File "C:\WISENTIA_Q\wisentia\venv\Lib\site-packages\rest_framework\decorators.py", line 50, in handler
    return func(*args, **kwargs)
           ^^^^^^^^^^^^^^^^^^^^^
  File "C:\WISENTIA_Q\wisentia\wisentia_backend\users\views.py", line 121, in register
    cursor.execute("""
  File "C:\WISENTIA_Q\wisentia\venv\Lib\site-packages\django\db\backends\utils.py", line 122, in execute
    return super().execute(sql, params)
           ^^^^^^^^^^^^^^^^^^^^^^^^^^^^
  File "C:\WISENTIA_Q\wisentia\venv\Lib\site-packages\django\db\backends\utils.py", line 79, in execute
    return self._execute_with_wrappers(
           ^^^^^^^^^^^^^^^^^^^^^^^^^^^^
  File "C:\WISENTIA_Q\wisentia\venv\Lib\site-packages\django\db\backends\utils.py", line 92, in _execute_with_wrappers
    return executor(sql, params, many, context)
           ^^^^^^^^^^^^^^^^^^^^^^^^^^^^^^^^^^^^
  File "C:\WISENTIA_Q\wisentia\venv\Lib\site-packages\django\db\backends\utils.py", line 100, in _execute
    with self.db.wrap_database_errors:
  File "C:\WISENTIA_Q\wisentia\venv\Lib\site-packages\django\db\utils.py", line 91, in __exit__
    raise dj_exc_value.with_traceback(traceback) from exc_value
  File "C:\WISENTIA_Q\wisentia\venv\Lib\site-packages\django\db\backends\utils.py", line 105, in _execute
    return self.cursor.execute(sql, params)
           ^^^^^^^^^^^^^^^^^^^^^^^^^^^^^^^^
  File "C:\WISENTIA_Q\wisentia\venv\Lib\site-packages\mssql\base.py", line 677, in execute
    return self.cursor.execute(sql, params)
           ^^^^^^^^^^^^^^^^^^^^^^^^^^^^^^^^
django.db.utils.IntegrityError: ('23000', "[23000] [Microsoft][ODBC Driver 17 for SQL Server][SQL Server]Violation of UNIQUE KEY constraint 'UQ__Users__6D19B83B36C6A55E'. Cannot insert duplicate key in object 'dbo.Users'. The duplicate key value is (). (2627) (SQLExecDirectW); [23000] [Microsoft][ODBC Driver 17 for SQL Server][SQL Server]The statement has been terminated. (3621)")

ERROR 2025-04-08 18:40:28,342 log 133896 130188 Internal Server Error: /api/auth/register/
ERROR 2025-04-08 18:40:28,343 basehttp 133896 130188 "POST /api/auth/register/ HTTP/1.1" 500 4803
ERROR 2025-04-08 18:40:32,244 middleware 133896 130188 API Error: ('23000', "[23000] [Microsoft][ODBC Driver 17 for SQL Server][SQL Server]Violation of UNIQUE KEY constraint 'UQ__Users__6D19B83B36C6A55E'. Cannot insert duplicate key in object 'dbo.Users'. The duplicate key value is (). (2627) (SQLExecDirectW); [23000] [Microsoft][ODBC Driver 17 for SQL Server][SQL Server]The statement has been terminated. (3621)")
ERROR 2025-04-08 18:40:32,245 middleware 133896 130188 Traceback (most recent call last):
  File "C:\WISENTIA_Q\wisentia\venv\Lib\site-packages\django\db\backends\utils.py", line 105, in _execute
    return self.cursor.execute(sql, params)
           ^^^^^^^^^^^^^^^^^^^^^^^^^^^^^^^^
  File "C:\WISENTIA_Q\wisentia\venv\Lib\site-packages\mssql\base.py", line 677, in execute
    return self.cursor.execute(sql, params)
           ^^^^^^^^^^^^^^^^^^^^^^^^^^^^^^^^
pyodbc.IntegrityError: ('23000', "[23000] [Microsoft][ODBC Driver 17 for SQL Server][SQL Server]Violation of UNIQUE KEY constraint 'UQ__Users__6D19B83B36C6A55E'. Cannot insert duplicate key in object 'dbo.Users'. The duplicate key value is (). (2627) (SQLExecDirectW); [23000] [Microsoft][ODBC Driver 17 for SQL Server][SQL Server]The statement has been terminated. (3621)")

The above exception was the direct cause of the following exception:

Traceback (most recent call last):
  File "C:\WISENTIA_Q\wisentia\venv\Lib\site-packages\django\core\handlers\base.py", line 197, in _get_response
    response = wrapped_callback(request, *callback_args, **callback_kwargs)
               ^^^^^^^^^^^^^^^^^^^^^^^^^^^^^^^^^^^^^^^^^^^^^^^^^^^^^^^^^^^^
  File "C:\WISENTIA_Q\wisentia\venv\Lib\site-packages\django\views\decorators\csrf.py", line 65, in _view_wrapper
    return view_func(request, *args, **kwargs)
           ^^^^^^^^^^^^^^^^^^^^^^^^^^^^^^^^^^^
  File "C:\WISENTIA_Q\wisentia\venv\Lib\site-packages\django\views\generic\base.py", line 104, in view
    return self.dispatch(request, *args, **kwargs)
           ^^^^^^^^^^^^^^^^^^^^^^^^^^^^^^^^^^^^^^^
  File "C:\WISENTIA_Q\wisentia\venv\Lib\site-packages\rest_framework\views.py", line 515, in dispatch
    response = self.handle_exception(exc)
               ^^^^^^^^^^^^^^^^^^^^^^^^^^
  File "C:\WISENTIA_Q\wisentia\venv\Lib\site-packages\rest_framework\views.py", line 475, in handle_exception
    self.raise_uncaught_exception(exc)
  File "C:\WISENTIA_Q\wisentia\venv\Lib\site-packages\rest_framework\views.py", line 486, in raise_uncaught_exception
    raise exc
  File "C:\WISENTIA_Q\wisentia\venv\Lib\site-packages\rest_framework\views.py", line 512, in dispatch
    response = handler(request, *args, **kwargs)
               ^^^^^^^^^^^^^^^^^^^^^^^^^^^^^^^^^
  File "C:\WISENTIA_Q\wisentia\venv\Lib\site-packages\rest_framework\decorators.py", line 50, in handler
    return func(*args, **kwargs)
           ^^^^^^^^^^^^^^^^^^^^^
  File "C:\WISENTIA_Q\wisentia\wisentia_backend\users\views.py", line 121, in register
    cursor.execute("""
  File "C:\WISENTIA_Q\wisentia\venv\Lib\site-packages\django\db\backends\utils.py", line 122, in execute
    return super().execute(sql, params)
           ^^^^^^^^^^^^^^^^^^^^^^^^^^^^
  File "C:\WISENTIA_Q\wisentia\venv\Lib\site-packages\django\db\backends\utils.py", line 79, in execute
    return self._execute_with_wrappers(
           ^^^^^^^^^^^^^^^^^^^^^^^^^^^^
  File "C:\WISENTIA_Q\wisentia\venv\Lib\site-packages\django\db\backends\utils.py", line 92, in _execute_with_wrappers
    return executor(sql, params, many, context)
           ^^^^^^^^^^^^^^^^^^^^^^^^^^^^^^^^^^^^
  File "C:\WISENTIA_Q\wisentia\venv\Lib\site-packages\django\db\backends\utils.py", line 100, in _execute
    with self.db.wrap_database_errors:
  File "C:\WISENTIA_Q\wisentia\venv\Lib\site-packages\django\db\utils.py", line 91, in __exit__
    raise dj_exc_value.with_traceback(traceback) from exc_value
  File "C:\WISENTIA_Q\wisentia\venv\Lib\site-packages\django\db\backends\utils.py", line 105, in _execute
    return self.cursor.execute(sql, params)
           ^^^^^^^^^^^^^^^^^^^^^^^^^^^^^^^^
  File "C:\WISENTIA_Q\wisentia\venv\Lib\site-packages\mssql\base.py", line 677, in execute
    return self.cursor.execute(sql, params)
           ^^^^^^^^^^^^^^^^^^^^^^^^^^^^^^^^
django.db.utils.IntegrityError: ('23000', "[23000] [Microsoft][ODBC Driver 17 for SQL Server][SQL Server]Violation of UNIQUE KEY constraint 'UQ__Users__6D19B83B36C6A55E'. Cannot insert duplicate key in object 'dbo.Users'. The duplicate key value is (). (2627) (SQLExecDirectW); [23000] [Microsoft][ODBC Driver 17 for SQL Server][SQL Server]The statement has been terminated. (3621)")

ERROR 2025-04-08 18:40:32,246 log 133896 130188 Internal Server Error: /api/auth/register/
ERROR 2025-04-08 18:40:32,246 basehttp 133896 130188 "POST /api/auth/register/ HTTP/1.1" 500 4803
ERROR 2025-04-08 18:40:37,547 middleware 133896 130188 API Error: ('23000', "[23000] [Microsoft][ODBC Driver 17 for SQL Server][SQL Server]Violation of UNIQUE KEY constraint 'UQ__Users__6D19B83B36C6A55E'. Cannot insert duplicate key in object 'dbo.Users'. The duplicate key value is (). (2627) (SQLExecDirectW); [23000] [Microsoft][ODBC Driver 17 for SQL Server][SQL Server]The statement has been terminated. (3621)")
ERROR 2025-04-08 18:40:37,548 middleware 133896 130188 Traceback (most recent call last):
  File "C:\WISENTIA_Q\wisentia\venv\Lib\site-packages\django\db\backends\utils.py", line 105, in _execute
    return self.cursor.execute(sql, params)
           ^^^^^^^^^^^^^^^^^^^^^^^^^^^^^^^^
  File "C:\WISENTIA_Q\wisentia\venv\Lib\site-packages\mssql\base.py", line 677, in execute
    return self.cursor.execute(sql, params)
           ^^^^^^^^^^^^^^^^^^^^^^^^^^^^^^^^
pyodbc.IntegrityError: ('23000', "[23000] [Microsoft][ODBC Driver 17 for SQL Server][SQL Server]Violation of UNIQUE KEY constraint 'UQ__Users__6D19B83B36C6A55E'. Cannot insert duplicate key in object 'dbo.Users'. The duplicate key value is (). (2627) (SQLExecDirectW); [23000] [Microsoft][ODBC Driver 17 for SQL Server][SQL Server]The statement has been terminated. (3621)")

The above exception was the direct cause of the following exception:

Traceback (most recent call last):
  File "C:\WISENTIA_Q\wisentia\venv\Lib\site-packages\django\core\handlers\base.py", line 197, in _get_response
    response = wrapped_callback(request, *callback_args, **callback_kwargs)
               ^^^^^^^^^^^^^^^^^^^^^^^^^^^^^^^^^^^^^^^^^^^^^^^^^^^^^^^^^^^^
  File "C:\WISENTIA_Q\wisentia\venv\Lib\site-packages\django\views\decorators\csrf.py", line 65, in _view_wrapper
    return view_func(request, *args, **kwargs)
           ^^^^^^^^^^^^^^^^^^^^^^^^^^^^^^^^^^^
  File "C:\WISENTIA_Q\wisentia\venv\Lib\site-packages\django\views\generic\base.py", line 104, in view
    return self.dispatch(request, *args, **kwargs)
           ^^^^^^^^^^^^^^^^^^^^^^^^^^^^^^^^^^^^^^^
  File "C:\WISENTIA_Q\wisentia\venv\Lib\site-packages\rest_framework\views.py", line 515, in dispatch
    response = self.handle_exception(exc)
               ^^^^^^^^^^^^^^^^^^^^^^^^^^
  File "C:\WISENTIA_Q\wisentia\venv\Lib\site-packages\rest_framework\views.py", line 475, in handle_exception
    self.raise_uncaught_exception(exc)
  File "C:\WISENTIA_Q\wisentia\venv\Lib\site-packages\rest_framework\views.py", line 486, in raise_uncaught_exception
    raise exc
  File "C:\WISENTIA_Q\wisentia\venv\Lib\site-packages\rest_framework\views.py", line 512, in dispatch
    response = handler(request, *args, **kwargs)
               ^^^^^^^^^^^^^^^^^^^^^^^^^^^^^^^^^
  File "C:\WISENTIA_Q\wisentia\venv\Lib\site-packages\rest_framework\decorators.py", line 50, in handler
    return func(*args, **kwargs)
           ^^^^^^^^^^^^^^^^^^^^^
  File "C:\WISENTIA_Q\wisentia\wisentia_backend\users\views.py", line 121, in register
    cursor.execute("""
  File "C:\WISENTIA_Q\wisentia\venv\Lib\site-packages\django\db\backends\utils.py", line 122, in execute
    return super().execute(sql, params)
           ^^^^^^^^^^^^^^^^^^^^^^^^^^^^
  File "C:\WISENTIA_Q\wisentia\venv\Lib\site-packages\django\db\backends\utils.py", line 79, in execute
    return self._execute_with_wrappers(
           ^^^^^^^^^^^^^^^^^^^^^^^^^^^^
  File "C:\WISENTIA_Q\wisentia\venv\Lib\site-packages\django\db\backends\utils.py", line 92, in _execute_with_wrappers
    return executor(sql, params, many, context)
           ^^^^^^^^^^^^^^^^^^^^^^^^^^^^^^^^^^^^
  File "C:\WISENTIA_Q\wisentia\venv\Lib\site-packages\django\db\backends\utils.py", line 100, in _execute
    with self.db.wrap_database_errors:
  File "C:\WISENTIA_Q\wisentia\venv\Lib\site-packages\django\db\utils.py", line 91, in __exit__
    raise dj_exc_value.with_traceback(traceback) from exc_value
  File "C:\WISENTIA_Q\wisentia\venv\Lib\site-packages\django\db\backends\utils.py", line 105, in _execute
    return self.cursor.execute(sql, params)
           ^^^^^^^^^^^^^^^^^^^^^^^^^^^^^^^^
  File "C:\WISENTIA_Q\wisentia\venv\Lib\site-packages\mssql\base.py", line 677, in execute
    return self.cursor.execute(sql, params)
           ^^^^^^^^^^^^^^^^^^^^^^^^^^^^^^^^
django.db.utils.IntegrityError: ('23000', "[23000] [Microsoft][ODBC Driver 17 for SQL Server][SQL Server]Violation of UNIQUE KEY constraint 'UQ__Users__6D19B83B36C6A55E'. Cannot insert duplicate key in object 'dbo.Users'. The duplicate key value is (). (2627) (SQLExecDirectW); [23000] [Microsoft][ODBC Driver 17 for SQL Server][SQL Server]The statement has been terminated. (3621)")

ERROR 2025-04-08 18:40:37,549 log 133896 130188 Internal Server Error: /api/auth/register/
ERROR 2025-04-08 18:40:37,549 basehttp 133896 130188 "POST /api/auth/register/ HTTP/1.1" 500 4803
ERROR 2025-04-08 18:41:00,395 middleware 133896 130188 API Error: ('23000', "[23000] [Microsoft][ODBC Driver 17 for SQL Server][SQL Server]Violation of UNIQUE KEY constraint 'UQ__Users__6D19B83B36C6A55E'. Cannot insert duplicate key in object 'dbo.Users'. The duplicate key value is (). (2627) (SQLExecDirectW); [23000] [Microsoft][ODBC Driver 17 for SQL Server][SQL Server]The statement has been terminated. (3621)")
ERROR 2025-04-08 18:41:00,396 middleware 133896 130188 Traceback (most recent call last):
  File "C:\WISENTIA_Q\wisentia\venv\Lib\site-packages\django\db\backends\utils.py", line 105, in _execute
    return self.cursor.execute(sql, params)
           ^^^^^^^^^^^^^^^^^^^^^^^^^^^^^^^^
  File "C:\WISENTIA_Q\wisentia\venv\Lib\site-packages\mssql\base.py", line 677, in execute
    return self.cursor.execute(sql, params)
           ^^^^^^^^^^^^^^^^^^^^^^^^^^^^^^^^
pyodbc.IntegrityError: ('23000', "[23000] [Microsoft][ODBC Driver 17 for SQL Server][SQL Server]Violation of UNIQUE KEY constraint 'UQ__Users__6D19B83B36C6A55E'. Cannot insert duplicate key in object 'dbo.Users'. The duplicate key value is (). (2627) (SQLExecDirectW); [23000] [Microsoft][ODBC Driver 17 for SQL Server][SQL Server]The statement has been terminated. (3621)")

The above exception was the direct cause of the following exception:

Traceback (most recent call last):
  File "C:\WISENTIA_Q\wisentia\venv\Lib\site-packages\django\core\handlers\base.py", line 197, in _get_response
    response = wrapped_callback(request, *callback_args, **callback_kwargs)
               ^^^^^^^^^^^^^^^^^^^^^^^^^^^^^^^^^^^^^^^^^^^^^^^^^^^^^^^^^^^^
  File "C:\WISENTIA_Q\wisentia\venv\Lib\site-packages\django\views\decorators\csrf.py", line 65, in _view_wrapper
    return view_func(request, *args, **kwargs)
           ^^^^^^^^^^^^^^^^^^^^^^^^^^^^^^^^^^^
  File "C:\WISENTIA_Q\wisentia\venv\Lib\site-packages\django\views\generic\base.py", line 104, in view
    return self.dispatch(request, *args, **kwargs)
           ^^^^^^^^^^^^^^^^^^^^^^^^^^^^^^^^^^^^^^^
  File "C:\WISENTIA_Q\wisentia\venv\Lib\site-packages\rest_framework\views.py", line 515, in dispatch
    response = self.handle_exception(exc)
               ^^^^^^^^^^^^^^^^^^^^^^^^^^
  File "C:\WISENTIA_Q\wisentia\venv\Lib\site-packages\rest_framework\views.py", line 475, in handle_exception
    self.raise_uncaught_exception(exc)
  File "C:\WISENTIA_Q\wisentia\venv\Lib\site-packages\rest_framework\views.py", line 486, in raise_uncaught_exception
    raise exc
  File "C:\WISENTIA_Q\wisentia\venv\Lib\site-packages\rest_framework\views.py", line 512, in dispatch
    response = handler(request, *args, **kwargs)
               ^^^^^^^^^^^^^^^^^^^^^^^^^^^^^^^^^
  File "C:\WISENTIA_Q\wisentia\venv\Lib\site-packages\rest_framework\decorators.py", line 50, in handler
    return func(*args, **kwargs)
           ^^^^^^^^^^^^^^^^^^^^^
  File "C:\WISENTIA_Q\wisentia\wisentia_backend\users\views.py", line 121, in register
    cursor.execute("""
  File "C:\WISENTIA_Q\wisentia\venv\Lib\site-packages\django\db\backends\utils.py", line 122, in execute
    return super().execute(sql, params)
           ^^^^^^^^^^^^^^^^^^^^^^^^^^^^
  File "C:\WISENTIA_Q\wisentia\venv\Lib\site-packages\django\db\backends\utils.py", line 79, in execute
    return self._execute_with_wrappers(
           ^^^^^^^^^^^^^^^^^^^^^^^^^^^^
  File "C:\WISENTIA_Q\wisentia\venv\Lib\site-packages\django\db\backends\utils.py", line 92, in _execute_with_wrappers
    return executor(sql, params, many, context)
           ^^^^^^^^^^^^^^^^^^^^^^^^^^^^^^^^^^^^
  File "C:\WISENTIA_Q\wisentia\venv\Lib\site-packages\django\db\backends\utils.py", line 100, in _execute
    with self.db.wrap_database_errors:
  File "C:\WISENTIA_Q\wisentia\venv\Lib\site-packages\django\db\utils.py", line 91, in __exit__
    raise dj_exc_value.with_traceback(traceback) from exc_value
  File "C:\WISENTIA_Q\wisentia\venv\Lib\site-packages\django\db\backends\utils.py", line 105, in _execute
    return self.cursor.execute(sql, params)
           ^^^^^^^^^^^^^^^^^^^^^^^^^^^^^^^^
  File "C:\WISENTIA_Q\wisentia\venv\Lib\site-packages\mssql\base.py", line 677, in execute
    return self.cursor.execute(sql, params)
           ^^^^^^^^^^^^^^^^^^^^^^^^^^^^^^^^
django.db.utils.IntegrityError: ('23000', "[23000] [Microsoft][ODBC Driver 17 for SQL Server][SQL Server]Violation of UNIQUE KEY constraint 'UQ__Users__6D19B83B36C6A55E'. Cannot insert duplicate key in object 'dbo.Users'. The duplicate key value is (). (2627) (SQLExecDirectW); [23000] [Microsoft][ODBC Driver 17 for SQL Server][SQL Server]The statement has been terminated. (3621)")

ERROR 2025-04-08 18:41:00,397 log 133896 130188 Internal Server Error: /api/auth/register/
ERROR 2025-04-08 18:41:00,397 basehttp 133896 130188 "POST /api/auth/register/ HTTP/1.1" 500 4803
INFO 2025-04-08 18:46:10,726 basehttp 133896 134152 "OPTIONS /api/auth/check-username/ HTTP/1.1" 200 0
WARNING 2025-04-08 18:46:10,750 log 133896 134152 Not Found: /api/auth/check-username/
WARNING 2025-04-08 18:46:10,750 basehttp 133896 134152 "POST /api/auth/check-username/ HTTP/1.1" 404 5599
WARNING 2025-04-08 18:46:11,699 log 133896 134152 Not Found: /api/auth/check-username/
WARNING 2025-04-08 18:46:11,699 basehttp 133896 134152 "POST /api/auth/check-username/ HTTP/1.1" 404 5599
INFO 2025-04-08 18:46:11,747 basehttp 133896 134152 "OPTIONS /api/auth/check-email/ HTTP/1.1" 200 0
WARNING 2025-04-08 18:46:11,758 log 133896 134152 Not Found: /api/auth/check-email/
WARNING 2025-04-08 18:46:11,760 basehttp 133896 134152 "POST /api/auth/check-email/ HTTP/1.1" 404 5590
WARNING 2025-04-08 18:47:06,452 log 133896 134152 Bad Request: /api/auth/register/
WARNING 2025-04-08 18:47:06,453 basehttp 133896 134152 "POST /api/auth/register/ HTTP/1.1" 400 44
WARNING 2025-04-08 18:47:09,802 log 133896 79792 Not Found: /api/auth/check-email/
WARNING 2025-04-08 18:47:09,803 log 133896 134152 Not Found: /api/auth/check-username/
WARNING 2025-04-08 18:47:09,805 basehttp 133896 79792 "POST /api/auth/check-email/ HTTP/1.1" 404 5590
WARNING 2025-04-08 18:47:09,805 basehttp 133896 134152 "POST /api/auth/check-username/ HTTP/1.1" 404 5599
WARNING 2025-04-08 18:47:10,597 log 133896 134152 Bad Request: /api/auth/register/
WARNING 2025-04-08 18:47:10,598 basehttp 133896 134152 "POST /api/auth/register/ HTTP/1.1" 400 44
WARNING 2025-04-08 18:47:14,960 log 133896 79792 Not Found: /api/auth/check-email/
WARNING 2025-04-08 18:47:14,961 basehttp 133896 79792 "POST /api/auth/check-email/ HTTP/1.1" 404 5590
WARNING 2025-04-08 18:47:14,963 log 133896 134152 Not Found: /api/auth/check-username/
WARNING 2025-04-08 18:47:14,964 basehttp 133896 134152 "POST /api/auth/check-username/ HTTP/1.1" 404 5599
WARNING 2025-04-08 18:47:16,531 log 133896 134152 Bad Request: /api/auth/register/
WARNING 2025-04-08 18:47:16,532 basehttp 133896 134152 "POST /api/auth/register/ HTTP/1.1" 400 44
WARNING 2025-04-08 18:47:23,412 log 133896 134152 Not Found: /api/auth/check-username/
WARNING 2025-04-08 18:47:23,413 log 133896 79792 Not Found: /api/auth/check-email/
WARNING 2025-04-08 18:47:23,413 basehttp 133896 79792 "POST /api/auth/check-email/ HTTP/1.1" 404 5590
WARNING 2025-04-08 18:47:23,415 basehttp 133896 134152 "POST /api/auth/check-username/ HTTP/1.1" 404 5599
WARNING 2025-04-08 18:47:27,540 log 133896 134152 Not Found: /api/auth/check-email/
WARNING 2025-04-08 18:47:27,543 log 133896 79792 Not Found: /api/auth/check-username/
WARNING 2025-04-08 18:47:27,544 basehttp 133896 134152 "POST /api/auth/check-email/ HTTP/1.1" 404 5590
WARNING 2025-04-08 18:47:27,544 basehttp 133896 79792 "POST /api/auth/check-username/ HTTP/1.1" 404 5599
ERROR 2025-04-08 18:47:28,079 middleware 133896 79792 API Error: ('23000', "[23000] [Microsoft][ODBC Driver 17 for SQL Server][SQL Server]Violation of UNIQUE KEY constraint 'UQ__Users__6D19B83B36C6A55E'. Cannot insert duplicate key in object 'dbo.Users'. The duplicate key value is (<NULL>). (2627) (SQLExecDirectW); [23000] [Microsoft][ODBC Driver 17 for SQL Server][SQL Server]The statement has been terminated. (3621)")
ERROR 2025-04-08 18:47:28,079 middleware 133896 79792 Traceback (most recent call last):
  File "C:\WISENTIA_Q\wisentia\venv\Lib\site-packages\django\db\backends\utils.py", line 105, in _execute
    return self.cursor.execute(sql, params)
           ^^^^^^^^^^^^^^^^^^^^^^^^^^^^^^^^
  File "C:\WISENTIA_Q\wisentia\venv\Lib\site-packages\mssql\base.py", line 677, in execute
    return self.cursor.execute(sql, params)
           ^^^^^^^^^^^^^^^^^^^^^^^^^^^^^^^^
pyodbc.IntegrityError: ('23000', "[23000] [Microsoft][ODBC Driver 17 for SQL Server][SQL Server]Violation of UNIQUE KEY constraint 'UQ__Users__6D19B83B36C6A55E'. Cannot insert duplicate key in object 'dbo.Users'. The duplicate key value is (<NULL>). (2627) (SQLExecDirectW); [23000] [Microsoft][ODBC Driver 17 for SQL Server][SQL Server]The statement has been terminated. (3621)")

The above exception was the direct cause of the following exception:

Traceback (most recent call last):
  File "C:\WISENTIA_Q\wisentia\venv\Lib\site-packages\django\core\handlers\base.py", line 197, in _get_response
    response = wrapped_callback(request, *callback_args, **callback_kwargs)
               ^^^^^^^^^^^^^^^^^^^^^^^^^^^^^^^^^^^^^^^^^^^^^^^^^^^^^^^^^^^^
  File "C:\WISENTIA_Q\wisentia\venv\Lib\site-packages\django\views\decorators\csrf.py", line 65, in _view_wrapper
    return view_func(request, *args, **kwargs)
           ^^^^^^^^^^^^^^^^^^^^^^^^^^^^^^^^^^^
  File "C:\WISENTIA_Q\wisentia\venv\Lib\site-packages\django\views\generic\base.py", line 104, in view
    return self.dispatch(request, *args, **kwargs)
           ^^^^^^^^^^^^^^^^^^^^^^^^^^^^^^^^^^^^^^^
  File "C:\WISENTIA_Q\wisentia\venv\Lib\site-packages\rest_framework\views.py", line 515, in dispatch
    response = self.handle_exception(exc)
               ^^^^^^^^^^^^^^^^^^^^^^^^^^
  File "C:\WISENTIA_Q\wisentia\venv\Lib\site-packages\rest_framework\views.py", line 475, in handle_exception
    self.raise_uncaught_exception(exc)
  File "C:\WISENTIA_Q\wisentia\venv\Lib\site-packages\rest_framework\views.py", line 486, in raise_uncaught_exception
    raise exc
  File "C:\WISENTIA_Q\wisentia\venv\Lib\site-packages\rest_framework\views.py", line 512, in dispatch
    response = handler(request, *args, **kwargs)
               ^^^^^^^^^^^^^^^^^^^^^^^^^^^^^^^^^
  File "C:\WISENTIA_Q\wisentia\venv\Lib\site-packages\rest_framework\decorators.py", line 50, in handler
    return func(*args, **kwargs)
           ^^^^^^^^^^^^^^^^^^^^^
  File "C:\WISENTIA_Q\wisentia\wisentia_backend\users\views.py", line 121, in register
    cursor.execute("""
  File "C:\WISENTIA_Q\wisentia\venv\Lib\site-packages\django\db\backends\utils.py", line 122, in execute
    return super().execute(sql, params)
           ^^^^^^^^^^^^^^^^^^^^^^^^^^^^
  File "C:\WISENTIA_Q\wisentia\venv\Lib\site-packages\django\db\backends\utils.py", line 79, in execute
    return self._execute_with_wrappers(
           ^^^^^^^^^^^^^^^^^^^^^^^^^^^^
  File "C:\WISENTIA_Q\wisentia\venv\Lib\site-packages\django\db\backends\utils.py", line 92, in _execute_with_wrappers
    return executor(sql, params, many, context)
           ^^^^^^^^^^^^^^^^^^^^^^^^^^^^^^^^^^^^
  File "C:\WISENTIA_Q\wisentia\venv\Lib\site-packages\django\db\backends\utils.py", line 100, in _execute
    with self.db.wrap_database_errors:
  File "C:\WISENTIA_Q\wisentia\venv\Lib\site-packages\django\db\utils.py", line 91, in __exit__
    raise dj_exc_value.with_traceback(traceback) from exc_value
  File "C:\WISENTIA_Q\wisentia\venv\Lib\site-packages\django\db\backends\utils.py", line 105, in _execute
    return self.cursor.execute(sql, params)
           ^^^^^^^^^^^^^^^^^^^^^^^^^^^^^^^^
  File "C:\WISENTIA_Q\wisentia\venv\Lib\site-packages\mssql\base.py", line 677, in execute
    return self.cursor.execute(sql, params)
           ^^^^^^^^^^^^^^^^^^^^^^^^^^^^^^^^
django.db.utils.IntegrityError: ('23000', "[23000] [Microsoft][ODBC Driver 17 for SQL Server][SQL Server]Violation of UNIQUE KEY constraint 'UQ__Users__6D19B83B36C6A55E'. Cannot insert duplicate key in object 'dbo.Users'. The duplicate key value is (<NULL>). (2627) (SQLExecDirectW); [23000] [Microsoft][ODBC Driver 17 for SQL Server][SQL Server]The statement has been terminated. (3621)")

ERROR 2025-04-08 18:47:28,081 log 133896 79792 Internal Server Error: /api/auth/register/
ERROR 2025-04-08 18:47:28,082 basehttp 133896 79792 "POST /api/auth/register/ HTTP/1.1" 500 4821
INFO 2025-04-08 18:50:42,062 autoreload 133896 126100 C:\WISENTIA_Q\wisentia\wisentia_backend\users\views.py changed, reloading.
INFO 2025-04-08 18:50:43,996 autoreload 133388 89904 Watching for file changes with StatReloader
WARNING 2025-04-08 18:53:12,501 log 133388 110180 Not Found: /api/auth/check-username/
WARNING 2025-04-08 18:53:12,502 basehttp 133388 110180 "POST /api/auth/check-username/ HTTP/1.1" 404 5599
WARNING 2025-04-08 18:53:18,160 log 133388 110180 Not Found: /api/auth/check-email/
WARNING 2025-04-08 18:53:18,161 basehttp 133388 110180 "POST /api/auth/check-email/ HTTP/1.1" 404 5590
WARNING 2025-04-08 18:53:21,029 log 133388 110180 Not Found: /api/auth/check-email/
WARNING 2025-04-08 18:53:21,030 basehttp 133388 110180 "POST /api/auth/check-email/ HTTP/1.1" 404 5590
WARNING 2025-04-08 18:53:22,438 log 133388 110180 Not Found: /api/auth/check-username/
WARNING 2025-04-08 18:53:22,438 basehttp 133388 110180 "POST /api/auth/check-username/ HTTP/1.1" 404 5599
ERROR 2025-04-08 18:53:34,630 log 133388 110180 Internal Server Error: /api/auth/register/
ERROR 2025-04-08 18:53:34,631 basehttp 133388 110180 "POST /api/auth/register/ HTTP/1.1" 500 57
INFO 2025-04-08 18:56:32,896 autoreload 133388 89904 C:\WISENTIA_Q\wisentia\wisentia_backend\users\views.py changed, reloading.
INFO 2025-04-08 18:56:34,259 autoreload 139528 135252 Watching for file changes with StatReloader
INFO 2025-04-08 19:01:31,454 autoreload 139528 135252 C:\WISENTIA_Q\wisentia\wisentia_backend\users\views.py changed, reloading.
INFO 2025-04-08 19:01:32,552 autoreload 139132 140684 Watching for file changes with StatReloader
WARNING 2025-04-08 19:02:55,587 log 139132 136020 Bad Request: /api/auth/register/
WARNING 2025-04-08 19:02:55,588 basehttp 139132 136020 "POST /api/auth/register/ HTTP/1.1" 400 35
WARNING 2025-04-08 19:03:00,439 log 139132 136020 Bad Request: /api/auth/register/
WARNING 2025-04-08 19:03:00,439 basehttp 139132 136020 "POST /api/auth/register/ HTTP/1.1" 400 32
ERROR 2025-04-08 19:03:04,055 log 139132 136020 Internal Server Error: /api/auth/register/
ERROR 2025-04-08 19:03:04,055 basehttp 139132 136020 "POST /api/auth/register/ HTTP/1.1" 500 57
INFO 2025-04-08 19:07:08,900 autoreload 135676 134588 Watching for file changes with StatReloader
WARNING 2025-04-08 19:07:41,659 log 135676 135188 Bad Request: /api/auth/register/
WARNING 2025-04-08 19:07:41,659 basehttp 135676 135188 "POST /api/auth/register/ HTTP/1.1" 400 32
ERROR 2025-04-08 19:07:47,020 log 135676 135188 Internal Server Error: /api/auth/register/
ERROR 2025-04-08 19:07:47,021 basehttp 135676 135188 "POST /api/auth/register/ HTTP/1.1" 500 57
WARNING 2025-04-08 19:07:48,091 log 135676 135188 Bad Request: /api/auth/register/
WARNING 2025-04-08 19:07:48,092 basehttp 135676 135188 "POST /api/auth/register/ HTTP/1.1" 400 35
WARNING 2025-04-08 19:07:52,890 log 135676 135188 Bad Request: /api/auth/register/
WARNING 2025-04-08 19:07:52,891 basehttp 135676 135188 "POST /api/auth/register/ HTTP/1.1" 400 32
ERROR 2025-04-08 19:08:09,004 log 135676 135188 Internal Server Error: /api/auth/register/
ERROR 2025-04-08 19:08:09,005 basehttp 135676 135188 "POST /api/auth/register/ HTTP/1.1" 500 57
INFO 2025-04-08 19:10:41,687 autoreload 135676 134588 C:\WISENTIA_Q\wisentia\wisentia_backend\users\views.py changed, reloading.
INFO 2025-04-08 19:10:42,541 autoreload 140092 106628 Watching for file changes with StatReloader
ERROR 2025-04-08 19:17:01,174 log 140092 138756 Internal Server Error: /api/auth/register/
ERROR 2025-04-08 19:17:01,174 basehttp 140092 138756 "POST /api/auth/register/ HTTP/1.1" 500 75
WARNING 2025-04-08 19:19:23,444 log 140092 138756 Bad Request: /api/auth/register/
WARNING 2025-04-08 19:19:23,446 basehttp 140092 138756 "POST /api/auth/register/ HTTP/1.1" 400 35
INFO 2025-04-08 19:22:13,723 autoreload 140092 106628 C:\WISENTIA_Q\wisentia\wisentia_backend\users\views.py changed, reloading.
INFO 2025-04-08 19:22:16,874 autoreload 127840 127240 Watching for file changes with StatReloader
INFO 2025-04-08 20:46:07,872 autoreload 122836 133712 Watching for file changes with StatReloader
INFO 2025-04-08 20:48:27,491 basehttp 122836 120652 "OPTIONS /api/auth/login/ HTTP/1.1" 200 0
WARNING 2025-04-08 20:48:27,532 log 122836 120652 Unauthorized: /api/auth/login/
WARNING 2025-04-08 20:48:27,533 basehttp 122836 120652 "POST /api/auth/login/ HTTP/1.1" 401 31
WARNING 2025-04-08 20:48:37,972 log 122836 120652 Unauthorized: /api/auth/login/
WARNING 2025-04-08 20:48:37,974 basehttp 122836 120652 "POST /api/auth/login/ HTTP/1.1" 401 31
INFO 2025-04-08 20:48:55,767 basehttp 122836 120652 "POST /api/auth/login/ HTTP/1.1" 200 492
INFO 2025-04-08 20:51:35,246 basehttp 122836 6292 "OPTIONS /api/auth/register/ HTTP/1.1" 200 0
WARNING 2025-04-08 20:51:35,270 log 122836 6292 Bad Request: /api/auth/register/
WARNING 2025-04-08 20:51:35,270 basehttp 122836 6292 "POST /api/auth/register/ HTTP/1.1" 400 44
ERROR 2025-04-08 20:52:09,156 log 122836 6292 Internal Server Error: /api/auth/register/
ERROR 2025-04-08 20:52:09,156 basehttp 122836 6292 "POST /api/auth/register/ HTTP/1.1" 500 388
INFO 2025-04-08 20:55:10,139 autoreload 118924 137336 Watching for file changes with StatReloader
ERROR 2025-04-08 20:57:47,183 log 118924 127264 Internal Server Error: /api/auth/register/
ERROR 2025-04-08 20:57:47,184 basehttp 118924 127264 "POST /api/auth/register/ HTTP/1.1" 500 388
INFO 2025-04-08 20:59:15,200 autoreload 118924 137336 C:\WISENTIA_Q\wisentia\wisentia_backend\users\views.py changed, reloading.
INFO 2025-04-08 20:59:16,342 autoreload 133816 130280 Watching for file changes with StatReloader
ERROR 2025-04-08 20:59:48,831 log 133816 131616 Internal Server Error: /api/auth/register/
ERROR 2025-04-08 20:59:48,832 basehttp 133816 131616 "POST /api/auth/register/ HTTP/1.1" 500 108
INFO 2025-04-08 21:05:42,043 autoreload 103056 139460 Watching for file changes with StatReloader
INFO 2025-04-08 21:06:02,726 autoreload 139072 136892 Watching for file changes with StatReloader
INFO 2025-04-08 21:06:50,200 autoreload 122000 135128 Watching for file changes with StatReloader
ERROR 2025-04-08 21:08:42,589 log 122000 109412 Internal Server Error: /api/auth/register/
ERROR 2025-04-08 21:08:42,591 basehttp 122000 109412 "POST /api/auth/register/ HTTP/1.1" 500 108
INFO 2025-04-08 21:10:52,132 autoreload 122000 135128 C:\WISENTIA_Q\wisentia\wisentia_backend\users\views.py changed, reloading.
INFO 2025-04-08 21:10:53,205 autoreload 140468 135120 Watching for file changes with StatReloader
INFO 2025-04-08 21:11:06,284 autoreload 140468 135120 C:\WISENTIA_Q\wisentia\wisentia_backend\users\views.py changed, reloading.
INFO 2025-04-08 21:11:07,385 autoreload 136012 96972 Watching for file changes with StatReloader
INFO 2025-04-08 21:11:48,721 autoreload 136012 96972 C:\WISENTIA_Q\wisentia\wisentia_backend\wisentia_backend\settings.py changed, reloading.
INFO 2025-04-08 21:13:23,520 autoreload 117016 69308 Watching for file changes with StatReloader
INFO 2025-04-08 21:14:18,434 autoreload 117016 69308 C:\WISENTIA_Q\wisentia\wisentia_backend\wisentia_backend\settings.py changed, reloading.
INFO 2025-04-08 21:14:19,555 autoreload 126704 135120 Watching for file changes with StatReloader
INFO 2025-04-08 21:14:51,142 autoreload 126704 135120 C:\WISENTIA_Q\wisentia\wisentia_backend\users\views.py changed, reloading.
INFO 2025-04-08 21:14:52,170 autoreload 135176 140668 Watching for file changes with StatReloader
INFO 2025-04-08 21:15:17,580 basehttp 135176 85652 "POST /api/auth/register/ HTTP/1.1" 201 510
INFO 2025-04-08 21:16:04,060 autoreload 135176 140668 C:\WISENTIA_Q\wisentia\wisentia_backend\wisentia_backend\settings.py changed, reloading.
INFO 2025-04-08 21:16:05,108 autoreload 128204 128052 Watching for file changes with StatReloader
INFO 2025-04-08 21:16:28,589 basehttp 128204 94912 "POST /api/auth/register/ HTTP/1.1" 201 510
WARNING 2025-04-08 21:21:07,515 log 128204 94912 Bad Request: /api/auth/register/
WARNING 2025-04-08 21:21:07,515 basehttp 128204 94912 "POST /api/auth/register/ HTTP/1.1" 400 44
WARNING 2025-04-08 21:22:17,570 log 128204 136284 Bad Request: /api/auth/register/
WARNING 2025-04-08 21:22:17,571 basehttp 128204 136284 "POST /api/auth/register/ HTTP/1.1" 400 44
INFO 2025-04-08 21:22:21,097 basehttp 128204 136284 "POST /api/auth/register/ HTTP/1.1" 201 522
INFO 2025-04-09 01:31:44,927 basehttp 128204 129012 "OPTIONS /api/auth/login/ HTTP/1.1" 200 0
INFO 2025-04-09 01:39:49,293 basehttp 128204 130332 "OPTIONS /api/auth/login/ HTTP/1.1" 200 0
INFO 2025-04-09 01:40:11,862 basehttp 128204 130332 "OPTIONS /api/auth/login/ HTTP/1.1" 200 0
INFO 2025-04-09 02:32:37,957 basehttp 128204 133960 "OPTIONS /api/auth/login/ HTTP/1.1" 200 0
INFO 2025-04-09 02:32:38,082 basehttp 128204 133960 "POST /api/auth/login/ HTTP/1.1" 200 492
INFO 2025-04-09 04:24:42,230 basehttp 128204 11960 "POST /api/auth/login/ HTTP/1.1" 200 492
INFO 2025-04-09 18:22:03,450 autoreload 32792 8844 Watching for file changes with StatReloader
INFO 2025-04-09 18:22:57,275 autoreload 36888 33736 Watching for file changes with StatReloader
